Workbook

Sheet 25级保育1班
A1: 序号 | B1: 姓名 | C1: 考号 | D1: 学号 | E1: 语文 | F1: 数学 | G1: 英语 | H1: 学前儿童发展心理 | I1: 学前儿童卫生保健 | J1: 学前教育基础知识 | K1: 总分 | L1: 排名
A2: 1 | B2: 陈李红 | C2: 1117 | D2: ==VLOOKUP(B2,[1]在校生综合信息查询!$A$2:$C$41,2,0) -> 25q770101025 | E2: 84 | F2: 24 | G2: 24 | H2: 21 | I2: 33 | J2: 20 | K2: 206
A3: 2 | B3: 陈紫琳 | C3: 1126 | D3: ==VLOOKUP(B3,[1]在校生综合信息查询!$A$2:$C$41,2,0) -> 25q740101023 | E3: 12 | F3: 8 | G3: 19 | H3: 12 | I3: 19 | J3: 3 | K3: 73
A4: 3 | B4: 陈紫伊 | C4: 1104 | D4: ==VLOOKUP(B4,[1]在校生综合信息查询!$A$2:$C$41,2,0) -> 25q770101010 | E4: 64 | F4: 12 | G4: 32.5 | H4: 25 | I4: 39 | J4: 18 | K4: 190.5
A5: 4 | B5: 范雨 | C5: 1101 | D5: ==VLOOKUP(B5,[1]在校生综合信息查询!$A$2:$C$41,2,0) -> 25q770101007 | E5: 39 | F5: 24 | G5: 23.5 | H5: 21 | I5: 63 | J5: 13 | K5: 183.5
A6: 5 | B6: 冯钥垚 | C6: 1125 | D6: ==VLOOKUP(B6,[1]在校生综合信息查询!$A$2:$C$41,2,0) -> 25q710103145 | E6: 68 | F6: 12 | G6: 29.5 | H6: 12 | I6: 26 | J6: 18 | K6: 165.5
A7: 6 | B7: 付雅琳 | C7: 1096 | D7: ==VLOOKUP(B7,[1]在校生综合信息查询!$A$2:$C$41,2,0) -> 25q770101034 | E7: 54 | F7: 32 | G7: 29 | H7: 33 | I7: 61 | J7: 18 | K7: 227
A8: 7 | B8: 付雨馨 | C8: 1108 | D8: ==VLOOKUP(B8,[1]在校生综合信息查询!$A$2:$C$41,2,0) -> 25q770101014 | E8: 54 | F8: 36 | G8: 29 | H8: 21 | I8: 41 | J8: 18 | K8: 199
A9: 8 | B9: 黄麟瑾 | C9: 1100 | D9: ==VLOOKUP(B9,[1]在校生综合信息查询!$A$2:$C$41,2,0) -> 25q770101005 | E9: 34 | F9: 39 | G9: 20.5 | H9: 27 | I9: 24 | J9: 15 | K9: 159.5
A10: 9 | B10: 李嘉琪 | C10: 1113 | D10: ==VLOOKUP(B10,[1]在校生综合信息查询!$A$2:$C$41,2,0) -> 25q770101020 | E10: 61 | F10: 12 | G10: 18.5 | H10: 24 | I10: 44 | J10: 27 | K10: 186.5
A11: 10 | B11: 李泳颉 | C11: 1098 | D11: ==VLOOKUP(B11,[1]在校生综合信息查询!$A$2:$C$41,2,0) -> 25q770101003 | E11: 15 | F11: 40 | G11: 29 | H11: 24 | I11: 44 | J11: 21 | K11: 173
A12: 11 | B12: 李泳谊 | C12: 1099 | D12: ==VLOOKUP(B12,[1]在校生综合信息查询!$A$2:$C$41,2,0) -> 25q770101004 | E12: 35 | F12: 16 | G12: 22 | H12: 12 | I12: 23 | J12: 15 | K12: 123
A13: 12 | B13: 李雨琴 | C13: 1114 | D13: ==VLOOKUP(B13,[1]在校生综合信息查询!$A$2:$C$41,2,0) -> 25q770101022 | E13: 52 | F13: 32 | G13: 16 | H13: 12 | I13: 30 | J13: 18 | K13: 160
... A33: 32 | B33: 朱语佳 | C33: 1111 | D33: ==VLOOKUP(B33,[1]在校生综合信息查询!$A$2:$C$41,2,0) -> 25q770101018 | E33: 83 | F33: 24 | G33: 20 | H33: 24 | I33: 43 | J33: 35 | K33: 229
B34: 牟梦昕
B35: 田金玲

Sheet 25级保育本方班
A1: 序号 | B1: 姓名 | C1: 考号 | D1: 学号 | E1: 语文 | F1: 数学 | G1: 英语 | H1: 学前儿童发展心理 | I1: 学前儿童卫生保健 | J1: 学前教育基础知识 | K1: 总分 | L1: 排名
A2: 1 | B2: 彭潇然 | E2: 109 | F2: 101 | G2: 82.5 | H2: 70 | I2: 92 | J2: 76 | K2: 530.5 | L2: 1
A3: 2 | B3: 沈玉欣 | E3: 96 | F3: 135 | G3: 71 | H3: 84 | I3: 75 | J3: 67 | K3: 528 | L3: 2
A4: 3 | B4: 王梦婷 | E4: 98 | F4: 95 | G4: 83 | H4: 84 | I4: 86 | J4: 80 | K4: 526 | L4: 3
A5: 4 | B5: 秦芸 | E5: 104 | F5: 130 | G5: 81 | H5: 50 | I5: 85 | J5: 50 | K5: 500 | L5: 4
A6: 5 | B6: 李梦蝶 | E6: 97 | F6: 109 | G6: 64 | H6: 65 | I6: 81 | J6: 80 | K6: 496 | L6: 5
A7: 6 | B7: 黄俊曦 | E7: 88 | F7: 82 | G7: 70 | H7: 71 | I7: 92 | J7: 71 | K7: 474 | L7: 6
A8: 7 | B8: 李重阳 | E8: 96 | F8: 124 | G8: 64 | H8: 60 | I8: 61 | J8: 61 | K8: 466 | L8: 7
A9: 8 | B9: 孙雨茹 | E9: 93 | F9: 74 | G9: 56 | H9: 66 | I9: 71 | J9: 56 | K9: 416 | L9: 8
A10: 9 | B10: 李宇馨 | E10: 83 | F10: 82 | G10: 52.5 | H10: 62 | I10: 63 | J10: 44 | K10: 386.5 | L10: 9
A11: 10 | B11: 霍静琳 | E11: 91 | F11: 67 | G11: 46.5 | H11: 53 | I11: 55 | J11: 60 | K11: 372.5 | L11: 10
A12: 11 | B12: 张雨嘉 | E12: 90 | F12: 49 | G12: 41 | H12: 60 | I12: 81 | J12: 35 | K12: 356 | L12: 11
A13: 12 | B13: 徐梓茹 | E13: 81 | F13: 41 | G13: 45 | H13: 56 | I13: 61 | J13: 52 | K13: 336 | L13: 12
... A26: 25 | B26: 王依依 | E26: 41 | F26: 16 | G26: 43.5 | H26: 30 | I26: 41 | J26: 23 | K26: 194.5 | L26: 25
A27: 26 | B27: 曹雅琳 | E27: 缺考 | F27: 缺考 | G27: 缺考 | H27: 缺考 | I27: 缺考 | J27: 缺考 | K27: 0 | L27: 26

Sheet 25级茶艺班
A1: 序号 | B1: 姓名 | C1: 考号 | D1: 学号 | E1: 语文 | F1: 数学 | G1: 英语 | H1: 中国旅游地理 | I1: 茶艺概论 | J1: 餐饮服务与管理 | K1: 总分 | L1: 排名
A2: 1 | B2: 陈湘 | C2: 1142 | D2: ==VLOOKUP(B2,[1]在校生综合信息查询!$A$68:$C$88,2,0) -> 25q740101068 | E2: 59 | F2: 12 | G2: 21 | H2: 52 | I2: 70 | J2: 44
A3: 2 | B3: 苟雨涵 | C3: 1133 | D3: ==VLOOKUP(B3,[1]在校生综合信息查询!$A$68:$C$88,2,0) -> 25q740101055 | E3: 0 | F3: 0 | G3: 0 | H3: 0 | I3: 0 | J3: 0
A4: 3 | B4: 何正莹 | C4: 1138 | D4: ==VLOOKUP(B4,[1]在校生综合信息查询!$A$68:$C$88,2,0) -> 25q740101064 | E4: 63 | F4: 20 | G4: 30 | H4: 38.5 | I4: 62 | J4: 39.5
A5: 4 | B5: 刘琳 | C5: 1144 | D5: ==VLOOKUP(B5,[1]在校生综合信息查询!$A$68:$C$88,2,0) -> 25q710103205 | E5: 26 | F5: 24 | G5: 13.5 | H5: 58 | I5: 55 | J5: 45.5
A6: 5 | B6: 刘欣雨 | C6: 1131 | D6: ==VLOOKUP(B6,[1]在校生综合信息查询!$A$68:$C$88,2,0) -> 25q740101049 | E6: 46 | F6: 12 | G6: 30.5 | H6: 44.5 | I6: 76 | J6: 25
A7: 6 | B7: 沈丹凤 | C7: 1140 | D7: ==VLOOKUP(B7,[1]在校生综合信息查询!$A$68:$C$88,2,0) -> 25q740101066 | E7: 37 | F7: 16 | G7: 30 | H7: 48.5 | I7: 68 | J7: 37
A8: 7 | B8: 王彩霞 | C8: 1132 | D8: ==VLOOKUP(B8,[1]在校生综合信息查询!$A$68:$C$88,2,0) -> 25q740101050 | E8: 81 | F8: 12 | G8: 37.5 | H8: 18 | I8: 88 | J8: 41.5
A9: 8 | B9: 杨晶 | C9: 1136 | D9: ==VLOOKUP(B9,[1]在校生综合信息查询!$A$68:$C$88,2,0) -> 25q740101058 | E9: 57 | F9: 12 | G9: 30.5 | H9: 54 | I9: 40 | J9: 54
A10: 9 | B10: 杨梦宇 | C10: 1143 | D10: ==VLOOKUP(B10,[1]在校生综合信息查询!$A$68:$C$88,2,0) -> #N/A | E10: 0 | F10: 0 | G10: 0 | H10: 0 | I10: 0 | J10: 0
A11: 10 | B11: 杨晰文 | C11: 1129 | D11: ==VLOOKUP(B11,[1]在校生综合信息查询!$A$68:$C$88,2,0) -> 25q740101002 | E11: 23 | F11: 12 | G11: 20 | H11: 28.5 | I11: 25 | J11: 35
A12: 11 | B12: 张诗雨 | C12: 1130 | D12: ==VLOOKUP(B12,[1]在校生综合信息查询!$A$68:$C$88,2,0) -> 25q740101004 | E12: 28 | F12: 8 | G12: 22 | H12: 39 | I12: 60 | J12: 41.5
A13: 12 | B13: 张雅萱 | C13: 1141 | D13: ==VLOOKUP(B13,[1]在校生综合信息查询!$A$68:$C$88,2,0) -> 25q740101067 | E13: 17 | F13: 16 | G13: 22 | H13: 31 | I13: 45 | J13: 36
... A15: 14 | B15: 赵雯怡 | C15: 1137 | D15: ==VLOOKUP(B15,[1]在校生综合信息查询!$A$68:$C$88,2,0) -> 25q740101060 | E15: 49 | F15: 20 | G15: 22.5 | H15: 38.5 | I15: 48 | J15: 28.5
A16: 15 | B16: 赵梓伊 | C16: 1134 | D16: ==VLOOKUP(B16,[1]在校生综合信息查询!$A$68:$C$88,2,0) -> 25q740101056 | E16: 0 | F16: 0 | G16: 0 | H16: 0 | I16: 0
A17: 16 | B17: 周国靖 | C17: 1128 | D17: ==VLOOKUP(B17,[1]在校生综合信息查询!$A$68:$C$88,2,0) -> 25q710103355 | E17: 56 | F17: 20 | G17: 21 | H17: 57 | I17: 66 | J17: 42.5
A18: 17 | B18: 祝荔檬 | C18: 1139 | D18: ==VLOOKUP(B18,[1]在校生综合信息查询!$A$68:$C$88,2,0) -> 25q740101065 | E18: 48 | F18: 8 | G18: 19 | H18: 64 | I18: 75 | J18: 40
A19: 18 | B19: 黄宇燕 | H19: 52 | I19: 55 | J19: 38.5

Sheet 25级电子（国防特色）班
A1: 序号 | B1: 姓名 | C1: 考号 | D1: 学号 | E1: 语文 | F1: 数学 | G1: 英语 | H1: 电工技术基础与技能实训 | I1: 电子技术基础与技能实训 | J1: 单片机技术与应用 | K1: 总分 | L1: 排名
A2: 1 | B2: 白宇城 | C2: 1369 | D2: ==VLOOKUP(B2,[1]在校生综合信息查询!$A$294:$C$348,2,0) -> 25q710103111 | E2: 30 | F2: 20 | G2: 22 | H2: 18 | I2: 18 | J2: 15
A3: 2 | B3: 曾展宏 | C3: 1349 | D3: ==VLOOKUP(B3,[1]在校生综合信息查询!$A$294:$C$348,2,0) -> 25q710103089 | E3: 22 | F3: 12 | G3: 23 | H3: 50 | I3: 12 | J3: 15
A4: 3 | B4: 陈树森 | C4: 1325 | D4: ==VLOOKUP(B4,[1]在校生综合信息查询!$A$294:$C$348,2,0) -> 25q710103093 | E4: 15 | F4: 20 | G4: 17 | H4: 16 | I4: 10
A5: 4 | B5: 邓杨 | C5: 1347 | D5: ==VLOOKUP(B5,[1]在校生综合信息查询!$A$294:$C$348,2,0) -> 25q710103087 | E5: 0 | F5: 0 | G5: 缺考
A6: 5 | B6: 俄底爸清 | C6: 1367 | D6: ==VLOOKUP(B6,[1]在校生综合信息查询!$A$294:$C$348,2,0) -> 25q710103109 | E6: 24 | F6: 28 | G6: 11 | H6: 18 | I6: 14 | J6: 29
A7: 6 | B7: 付俊熙 | C7: 1351 | D7: ==VLOOKUP(B7,[1]在校生综合信息查询!$A$294:$C$348,2,0) -> 25q710103091 | E7: 6 | F7: 32 | G7: 22.5 | H7: 16 | I7: 18 | J7: 33
A8: 7 | B8: 龚柯力 | C8: 1340 | D8: ==VLOOKUP(B8,[1]在校生综合信息查询!$A$294:$C$348,2,0) -> 25q710103080 | E8: 0 | F8: 0 | G8: 0
A9: 8 | B9: 郭松涛 | C9: 1375 | D9: ==VLOOKUP(B9,[1]在校生综合信息查询!$A$294:$C$348,2,0) -> #N/A | E9: 17 | F9: 24 | G9: 23.5 | H9: 20 | I9: 16 | J9: 21
A10: 9 | B10: 何东林 | C10: 1330 | D10: ==VLOOKUP(B10,[1]在校生综合信息查询!$A$294:$C$348,2,0) -> 25q710103068 | E10: 19 | F10: 36 | G10: 13.5 | H10: 16 | I10: 25 | J10: 26
A11: 10 | B11: 何家棋 | C11: 1366 | D11: ==VLOOKUP(B11,[1]在校生综合信息查询!$A$294:$C$348,2,0) -> 25q710103108 | E11: 6 | F11: 24 | G11: 23 | H11: 22 | I11: 18 | J11: 12
A12: 11 | B12: 胡凯荣 | C12: 1336 | D12: ==VLOOKUP(B12,[1]在校生综合信息查询!$A$294:$C$348,2,0) -> 25q710103075 | E12: 6 | F12: 28 | G12: 24.5 | H12: 16 | I12: 20 | J12: 18
A13: 12 | B13: 胡喻耀 | C13: 1372 | D13: ==VLOOKUP(B13,[1]在校生综合信息查询!$A$294:$C$348,2,0) -> 25q710103115 | E13: 11 | F13: 16 | G13: 12 | H13: 16 | I13: 10 | J13: 33
A14: 13 | B14: 黄炳富 | C14: 1368 | D14: ==VLOOKUP(B14,[1]在校生综合信息查询!$A$294:$C$348,2,0) -> 25q710103110 | E14: 15 | F14: 12 | G14: 18.5 | H14: 18 | I14: 18
A15: 14 | B15: 黄靖 | C15: 1331 | D15: ==VLOOKUP(B15,[1]在校生综合信息查询!$A$294:$C$348,2,0) -> 25q710103069 | E15: 11 | F15: 24 | G15: 19 | H15: 30 | I15: 23 | J15: 29
A16: 15 | B16: 黄舒伟 | C16: 1348 | D16: ==VLOOKUP(B16,[1]在校生综合信息查询!$A$294:$C$348,2,0) -> 25q710103088 | E16: 35 | F16: 16 | G16: 25 | H16: 22 | I16: 12 | J16: 27
A17: 16 | B17: 霍福杰 | C17: 1350 | D17: ==VLOOKUP(B17,[1]在校生综合信息查询!$A$294:$C$348,2,0) -> 25q710103090 | E17: 12 | F17: 20 | G17: 16.5 | H17: 18 | I17: 16 | J17: 21
A18: 17 | B18: 李金艺 | C18: 1370 | D18: ==VLOOKUP(B18,[1]在校生综合信息查询!$A$294:$C$348,2,0) -> 25q710103112 | E18: 6 | F18: 32 | G18: 19.5 | H18: 18 | I18: 14 | J18: 12
A19: 18 | B19: 李梦龙 | C19: 1364 | D19: ==VLOOKUP(B19,[1]在校生综合信息查询!$A$294:$C$348,2,0) -> 25q710103106 | E19: 9 | F19: 16 | G19: 23.5 | H19: 28 | I19: 26 | J19: 28
A20: 19 | B20: 李永 | C20: 1371 | D20: ==VLOOKUP(B20,[1]在校生综合信息查询!$A$294:$C$348,2,0) -> 25q710103113 | E20: 9 | F20: 24 | G20: 23 | H20: 14 | I20: 0
A21: 20 | B21: 李宇轩 | C21: 1332 | D21: ==VLOOKUP(B21,[1]在校生综合信息查询!$A$294:$C$348,2,0) -> 25q710103070 | E21: 15 | F21: 12 | G21: 14 | H21: 12 | I21: 16 | J21: 34.5
A22: 21 | B22: 凌磊 | C22: 1346 | D22: ==VLOOKUP(B22,[1]在校生综合信息查询!$A$294:$C$348,2,0) -> 25q710103086 | E22: 20 | F22: 28 | G22: 19 | H22: 34 | I22: 15 | J22: 30
A23: 22 | B23: 刘俊宇 | C23: 1360 | D23: ==VLOOKUP(B23,[1]在校生综合信息查询!$A$294:$C$348,2,0) -> 25q710103102 | E23: 9 | F23: —— | G23: 22 | H23: 14 | I23: 14 | J23: 30
A24: 23 | B24: 刘熙宇 | C24: 1365 | D24: ==VLOOKUP(B24,[1]在校生综合信息查询!$A$294:$C$348,2,0) -> 25q710103107 | E24: 23 | F24: 51 | G24: 29.5 | H24: 24 | I24: 20 | J24: 52.5
A25: 24 | B25: 刘志林 | C25: 1352 | D25: ==VLOOKUP(B25,[1]在校生综合信息查询!$A$294:$C$348,2,0) -> 25q710103092 | E25: 12 | F25: 24 | G25: 18.5 | H25: 24 | I25: 18 | J25: 15
A26: 25 | B26: 罗皓 | C26: 1354 | D26: ==VLOOKUP(B26,[1]在校生综合信息查询!$A$294:$C$348,2,0) -> 25q710103095 | E26: 11 | F26: 4 | G26: 36 | H26: 18 | I26: 16 | J26: 27
A27: 26 | B27: 罗皓轩 | C27: 1343 | D27: ==VLOOKUP(B27,[1]在校生综合信息查询!$A$294:$C$348,2,0) -> 25q710103083 | E27: 13 | F27: 32 | G27: 26 | H27: 18 | I27: 15 | J27: 27
A28: 27 | B28: 罗俊杰 | C28: 1345 | D28: ==VLOOKUP(B28,[1]在校生综合信息查询!$A$294:$C$348,2,0) -> 25q710103085 | E28: 9 | F28: 8 | G28: 16 | H28: 12 | I28: 16
A29: 28 | B29: 罗伊辰 | C29: 1334 | D29: ==VLOOKUP(B29,[1]在校生综合信息查询!$A$294:$C$348,2,0) -> 25q710103072 | E29: 15 | F29: 8 | G29: 29 | H29: 20 | I29: 18 | J29: 11.5
A30: 29 | B30: 彭家豪 | C30: 1359 | D30: ==VLOOKUP(B30,[1]在校生综合信息查询!$A$294:$C$348,2,0) -> 25q710103101 | E30: —— | F30: 20 | G30: 27 | H30: 20 | I30: 6 | J30: 30
A31: 30 | B31: 史毅 | C31: 1357 | D31: ==VLOOKUP(B31,[1]在校生综合信息查询!$A$294:$C$348,2,0) -> 25q710103099 | E31: 29 | F31: 30 | G31: 19 | H31: 27 | I31: 16 | J31: 29
A32: 31 | B32: 苏金宝 | C32: 1373 | D32: ==VLOOKUP(B32,[1]在校生综合信息查询!$A$294:$C$348,2,0) -> 25q710103116 | E32: 0 | F32: 0 | G32: 0
A33: 32 | B33: 唐鑫懿 | C33: 1363 | D33: ==VLOOKUP(B33,[1]在校生综合信息查询!$A$294:$C$348,2,0) -> 25q710103105 | E33: 6 | F33: 16 | G33: 25.5 | H33: 20 | I33: 16 | J33: 15
A34: 33 | B34: 王建平 | C34: 1341 | D34: ==VLOOKUP(B34,[1]在校生综合信息查询!$A$294:$C$348,2,0) -> 25q710103081 | E34: 6 | F34: 16 | G34: 13.5 | H34: 8 | I34: 14 | J34: 30
A35: 34 | B35: 王君浩 | C35: 1356 | D35: ==VLOOKUP(B35,[1]在校生综合信息查询!$A$294:$C$348,2,0) -> 25q710103097 | E35: 46 | F35: 12 | G35: 18.5 | H35: 40 | I35: 16 | J35: 21
A36: 35 | B36: 文玉祥 | C36: 1324 | D36: ==VLOOKUP(B36,[1]在校生综合信息查询!$A$294:$C$348,2,0) -> 25q710103067 | E36: 32 | F36: 32 | G36: 25.5 | H36: 30 | I36: 23 | J36: 51
A37: 36 | B37: 吴劲豪 | C37: 1377 | D37: ==VLOOKUP(B37,[1]在校生综合信息查询!$A$294:$C$348,2,0) -> 25q710103077 | E37: 9 | F37: 24 | G37: 20.5 | H37: 16 | I37: 12 | J37: 15
A38: 37 | B38: 吴至高 | C38: 1326 | D38: ==VLOOKUP(B38,[1]在校生综合信息查询!$A$294:$C$348,2,0) -> 25q710103100 | E38: 14 | F38: 12 | G38: 20.5 | H38: 22 | I38: 8 | J38: 21
A39: 38 | B39: 向鹏程 | C39: 1361 | D39: ==VLOOKUP(B39,[1]在校生综合信息查询!$A$294:$C$348,2,0) -> 25q710103071 | E39: 3 | F39: 8 | G39: 14.5 | H39: 6 | I39: 12
A40: 39 | B40: 严世豪 | C40: 1353 | D40: ==VLOOKUP(B40,[1]在校生综合信息查询!$A$294:$C$348,2,0) -> 25q710103114 | E40: 11 | F40: 4 | G40: 16 | H40: 16 | I40: 16 | J40: 27
...

Sheet 25级电子1班
A1: 序号 | B1: 姓名 | C1: 考号 | D1: 学号 | E1: 语文 | F1: 数学 | G1: 英语 | H1: 电工技术基础与技能实训 | I1: 电子技术基础与技能实训 | J1: 单片机技术与应用 | K1: 总分 | L1: 排名
A2: 1 | B2: 白雨佳 | C2: 1949 | D2: ==VLOOKUP(B2,[1]在校生综合信息查询!$A$89:$C$156,2,0) -> 25q710103340 | E2: 0 | F2: 32 | G2: 20.5 | H2: 0 | I2: 0 | J2: 0
A3: 2 | B3: 陈君统 | C3: 1941 | D3: ==VLOOKUP(B3,[1]在校生综合信息查询!$A$89:$C$156,2,0) -> 25q710103331 | E3: 15 | F3: 20 | G3: 15 | H3: 12 | I3: 14 | J3: 33
A4: 3 | B4: 陈旭焱 | C4: 1937 | D4: ==VLOOKUP(B4,[1]在校生综合信息查询!$A$89:$C$156,2,0) -> 25q710103326 | E4: 53 | F4: 35 | G4: 24 | H4: 24 | I4: 20 | J4: 50.5
A5: 4 | B5: 陈奕宇 | C5: 1960 | D5: ==VLOOKUP(B5,[1]在校生综合信息查询!$A$89:$C$156,2,0) -> 25q770303042
A6: 5 | B6: 翟崇宇 | C6: 1974 | D6: ==VLOOKUP(B6,[1]在校生综合信息查询!$A$89:$C$156,2,0) -> #N/A
A7: 6 | B7: 丁嘉豪 | C7: 1943 | D7: ==VLOOKUP(B7,[1]在校生综合信息查询!$A$89:$C$156,2,0) -> 25q710103333 | E7: 35 | F7: 12 | G7: 19.5 | H7: 28 | I7: 12 | J7: 24
A8: 7 | B8: 房竣 | C8: 1958 | D8: ==VLOOKUP(B8,[1]在校生综合信息查询!$A$89:$C$156,2,0) -> 25q770303019 | E8: 38 | F8: 20 | G8: 18 | H8: 28 | I8: 22 | J8: 14.5
A9: 8 | B9: 冯晨 | C9: 1963 | D9: ==VLOOKUP(B9,[1]在校生综合信息查询!$A$89:$C$156,2,0) -> 25q710201250 | E9: 19 | F9: 28 | G9: 24 | H9: 14 | I9: 18 | J9: 24
A10: 9 | B10: 符玉涵 | C10: 1959 | D10: ==VLOOKUP(B10,[1]在校生综合信息查询!$A$89:$C$156,2,0) -> 25q770303012 | H10: 18 | I10: 20 | J10: 21
A11: 10 | B11: 付鑫玥 | C11: 1914 | D11: ==VLOOKUP(B11,[1]在校生综合信息查询!$A$89:$C$156,2,0) -> 25q710103299 | E11: 63 | F11: 32 | G11: 19.5 | H11: 18 | I11: 14 | J11: 27
A12: 11 | B12: 高玉涵 | C12: 1970 | D12: ==VLOOKUP(B12,[1]在校生综合信息查询!$A$89:$C$156,2,0) -> 25q710103283 | E12: 3 | F12: 20 | G12: 32 | H12: 22 | I12: 16 | J12: 15
A13: 12 | B13: 高玉轩 | C13: 1916 | D13: ==VLOOKUP(B13,[1]在校生综合信息查询!$A$89:$C$156,2,0) -> 25q710103301 | E13: 3 | F13: 8 | G13: 13 | H13: 14 | I13: 18 | J13: 27
A14: 13 | B14: 黄鸿阳 | C14: 1944 | D14: ==VLOOKUP(B14,[1]在校生综合信息查询!$A$89:$C$156,2,0) -> 25q710103334 | E14: 51 | F14: 28 | G14: 14.5 | H14: 12 | I14: 16 | J14: 36
A15: 14 | B15: 黄佳豪 | C15: 1955 | D15: ==VLOOKUP(B15,[1]在校生综合信息查询!$A$89:$C$156,2,0) -> 25q710103350 | E15: 22 | F15: 12 | G15: 19 | H15: 28 | I15: 14 | J15: 18
A16: 15 | B16: 黄思宇 | C16: 1948 | D16: ==VLOOKUP(B16,[1]在校生综合信息查询!$A$89:$C$156,2,0) -> #N/A | E16: 3 | F16: 24 | G16: 22 | H16: 0 | I16: 6 | J16: 21
A17: 16 | B17: 黄鑫叙 | C17: 1925 | D17: ==VLOOKUP(B17,[1]在校生综合信息查询!$A$89:$C$156,2,0) -> 25q710103313 | E17: 22 | F17: 24 | G17: 15 | H17: 22 | I17: 16 | J17: 30
A18: 17 | B18: 黄梓桂 | C18: 1920 | D18: ==VLOOKUP(B18,[1]在校生综合信息查询!$A$89:$C$156,2,0) -> 25q710103307 | H18: 0 | I18: 0 | J18: 0
A19: 18 | B19: 江雨帆 | C19: 1966 | D19: ==VLOOKUP(B19,[1]在校生综合信息查询!$A$89:$C$156,2,0) -> 25q710103269 | E19: 33 | F19: 32 | G19: 23 | H19: 30 | I19: 20 | J19: 44
A20: 19 | B20: 姜博译 | C20: 1905 | D20: ==VLOOKUP(B20,[1]在校生综合信息查询!$A$89:$C$156,2,0) -> 25q660103116 | E20: 13 | F20: 8 | G20: 19.5 | H20: 18 | I20: 20 | J20: 21
A21: 20 | B21: 李凡志 | C21: 1973 | D21: ==VLOOKUP(B21,[1]在校生综合信息查询!$A$89:$C$156,2,0) -> 25q710201563 | E21: 15 | F21: 24 | G21: 22.5 | H21: 18 | I21: 24 | J21: 24
A22: 21 | B22: 李豪 | C22: 1933 | D22: ==VLOOKUP(B22,[1]在校生综合信息查询!$A$89:$C$156,2,0) -> 25q710103321 | E22: 21 | F22: 16 | G22: 23 | H22: 12 | I22: 15 | J22: 16
A23: 22 | B23: 李燕 | C23: 1961 | D23: ==VLOOKUP(B23,[1]在校生综合信息查询!$A$89:$C$156,2,0) -> 25q770101002 | E23: 35 | F23: 44 | G23: 25.5 | H23: 20 | I23: 6 | J23: 43
A24: 23 | B24: 李阳 | C24: 1926 | D24: ==VLOOKUP(B24,[1]在校生综合信息查询!$A$89:$C$156,2,0) -> 25q710103314 | E24: 13 | F24: 8 | G24: 16 | H24: 18 | I24: 16 | J24: 18
A25: 24 | B25: 李宇帆 | C25: 1940 | D25: ==VLOOKUP(B25,[1]在校生综合信息查询!$A$89:$C$156,2,0) -> 25q710103330
A26: 25 | B26: 李哲轩 | C26: 1928 | D26: ==VLOOKUP(B26,[1]在校生综合信息查询!$A$89:$C$156,2,0) -> 25q710103316 | E26: 16 | F26: 16 | G26: 21 | H26: 14 | I26: 12 | J26: 9
A27: 26 | B27: 梁志灏 | C27: 1906 | D27: ==VLOOKUP(B27,[1]在校生综合信息查询!$A$89:$C$156,2,0) -> 25q660103118 | E27: 9 | F27: 12 | G27: 18 | H27: 24 | I27: 18 | J27: 12
A28: 27 | B28: 廖家瑞 | C28: 1954 | D28: ==VLOOKUP(B28,[1]在校生综合信息查询!$A$89:$C$156,2,0) -> 25q710103347 | E28: 31 | F28: 24 | G28: 16 | H28: 16 | I28: 14 | J28: 33
A29: 28 | B29: 刘函林 | C29: 1930 | D29: ==VLOOKUP(B29,[1]在校生综合信息查询!$A$89:$C$156,2,0) -> 25q710103318 | E29: 9 | F29: 16 | G29: 16 | H29: 16 | I29: 14 | J29: 30
A30: 29 | B30: 罗杨凯 | C30: 1946 | D30: ==VLOOKUP(B30,[1]在校生综合信息查询!$A$89:$C$156,2,0) -> 25q710103336
A31: 30 | B31: 彭星富 | C31: 1950 | D31: ==VLOOKUP(B31,[1]在校生综合信息查询!$A$89:$C$156,2,0) -> 25q710103341
A32: 31 | B32: 乔杰 | C32: 1935 | D32: ==VLOOKUP(B32,[1]在校生综合信息查询!$A$89:$C$156,2,0) -> 25q710103324 | E32: 6 | F32: 16 | G32: 24.5 | H32: 20 | I32: 19 | J32: 24
A33: 32 | B33: 秦瑞新 | C33: 1922 | D33: ==VLOOKUP(B33,[1]在校生综合信息查询!$A$89:$C$156,2,0) -> 25q710103310 | E33: 49 | F33: 12 | G33: 20.5 | H33: 18 | I33: 20 | J33: 21
A34: 33 | B34: 权文博 | C34: 1910 | D34: ==VLOOKUP(B34,[1]在校生综合信息查询!$A$89:$C$156,2,0) -> 25q710103295 | E34: 63 | F34: 31 | G34: 61.5 | H34: 20 | I34: 18 | J34: 37
A35: 34 | B35: 孙宇豪 | C35: 1942 | D35: ==VLOOKUP(B35,[1]在校生综合信息查询!$A$89:$C$156,2,0) -> 25q710103332 | E35: 12 | F35: 32 | G35: 22.5 | H35: 8 | J35: 24
A36: 35 | B36: 孙梓怡 | C36: 1934 | D36: ==VLOOKUP(B36,[1]在校生综合信息查询!$A$89:$C$156,2,0) -> 25q710103271 | E36: 51 | F36: 20 | G36: 18.5 | H36: 27 | I36: 16 | J36: 27
A37: 36 | B37: 汤宇洁 | C37: 1952 | D37: ==VLOOKUP(B37,[1]在校生综合信息查询!$A$89:$C$156,2,0) -> 25q710103317 | E37: 3 | F37: 8 | G37: 21.5 | H37: 0 | I37: 8 | J37: 27
A38: 37 | B38: 田珂欣 | C38: 1938 | D38: ==VLOOKUP(B38,[1]在校生综合信息查询!$A$89:$C$156,2,0) -> 25q710103280
A39: 38 | B39: 万富强 | C39: 1927 | D39: ==VLOOKUP(B39,[1]在校生综合信息查询!$A$89:$C$156,2,0) -> 25q710103300 | E39: 8 | F39: 20 | G39: 20.5 | H39: 16 | I39: 18 | J39: 18
A40: 39 | B40: 王浩 | C40: 1953 | D40: ==VLOOKUP(B40,[1]在校生综合信息查询!$A$89:$C$156,2,0) -> 25q710103319 | E40: 6 | F40: 24 | G40: 22 | H40: 12 | I40: 4 | J40: 42
...

Sheet 25级电子2班
A1: 序号 | B1: 姓名 | C1: 考号 | D1: 学号 | E1: 语文 | F1: 数学 | G1: 英语 | H1: 电工技术基础与技能实训 | I1: 电子技术基础与技能实训 | J1: 单片机技术与应用 | K1: 总分 | L1: 排名
A2: 1 | B2: 车定远 | C2: 1269 | D2: ==VLOOKUP(B2,[1]在校生综合信息查询!$A$157:$C$222,2,0) -> 25q710103175 | E2: 6 | F2: 0 | G2: 18.5 | H2: 0 | I2: 0 | J2: 0 | K2: ==SUM(E2:J2) -> 24.5 | L2: ==RANK(K2,$K$2:K$66) -> 51
A3: 2 | B3: 陈楚元 | C3: 1277 | D3: ==VLOOKUP(B3,[1]在校生综合信息查询!$A$157:$C$222,2,0) -> 25q710103189 | E3: 0 | F3: 0 | G3: 24 | H3: 14 | I3: 12 | J3: 18 | K3: ==SUM(E3:J3) -> 68 | L3: ==RANK(K3,$K$2:K$66) -> 49
A4: 3 | B4: 陈嘉兴 | C4: 1276 | D4: ==VLOOKUP(B4,[1]在校生综合信息查询!$A$157:$C$222,2,0) -> 25q710103188 | E4: 0 | F4: 0 | G4: 0 | H4: 0 | I4: 0 | J4: 0 | K4: ==SUM(E4:J4) -> 0 | L4: ==RANK(K4,$K$2:K$66) -> 56
A5: 4 | B5: 陈思雨 | C5: 1284 | D5: ==VLOOKUP(B5,[1]在校生综合信息查询!$A$157:$C$222,2,0) -> 25q710103197 | E5: 16 | F5: 16 | G5: 22 | H5: 0 | I5: 20 | J5: 37 | K5: ==SUM(E5:J5) -> 111 | L5: ==RANK(K5,$K$2:K$66) -> 26
A6: 5 | B6: 陈烨霖 | C6: 1310 | D6: ==VLOOKUP(B6,[1]在校生综合信息查询!$A$157:$C$222,2,0) -> 25q710103290 | E6: 57 | F6: 12 | G6: 0 | H6: 0 | I6: 0 | J6: 0 | K6: ==SUM(E6:J6) -> 69 | L6: ==RANK(K6,$K$2:K$66) -> 48
A7: 6 | B7: 成俊豪 | C7: 1303 | D7: ==VLOOKUP(B7,[1]在校生综合信息查询!$A$157:$C$222,2,0) -> 25q710103185 | E7: 0 | F7: 0 | G7: 15.5 | H7: 0 | I7: 0 | J7: 0 | K7: ==SUM(E7:J7) -> 15.5 | L7: ==RANK(K7,$K$2:K$66) -> 53
A8: 7 | B8: 程思静 | C8: 1319 | D8: ==VLOOKUP(B8,[1]在校生综合信息查询!$A$157:$C$222,2,0) -> 25q710103281 | E8: 47 | F8: 37 | G8: 14.5 | H8: 34 | I8: 16 | J8: 29 | K8: ==SUM(E8:J8) -> 177.5 | L8: ==RANK(K8,$K$2:K$66) -> 7
A9: 8 | B9: 邓毅文 | C9: 1321 | D9: ==VLOOKUP(B9,[1]在校生综合信息查询!$A$157:$C$222,2,0) -> #N/A | E9: 3 | F9: 29 | G9: 21.5 | H9: 20 | I9: 18 | J9: 21 | K9: ==SUM(E9:J9) -> 112.5 | L9: ==RANK(K9,$K$2:K$66) -> 25
A10: 9 | B10: 底浩东 | C10: 1264 | D10: ==VLOOKUP(B10,[1]在校生综合信息查询!$A$157:$C$222,2,0) -> 25q710103170 | E10: 0 | F10: 0 | G10: 0 | H10: 0 | I10: 0 | J10: 0 | K10: ==SUM(E10:J10) -> 0 | L10: ==RANK(K10,$K$2:K$66) -> 56
A11: 10 | B11: 丁雨鑫 | C11: 1294 | D11: ==VLOOKUP(B11,[1]在校生综合信息查询!$A$157:$C$222,2,0) -> 25q710103211 | E11: 0 | F11: 0 | G11: 0 | H11: 0 | I11: 0 | J11: 0 | K11: ==SUM(E11:J11) -> 0 | L11: ==RANK(K11,$K$2:K$66) -> 56
A12: 11 | B12: 董济江 | C12: 1262 | D12: ==VLOOKUP(B12,[1]在校生综合信息查询!$A$157:$C$222,2,0) -> 25q710103168 | E12: 17 | F12: 20 | G12: 17 | H12: 18 | I12: 16 | J12: 43 | K12: ==SUM(E12:J12) -> 131 | L12: ==RANK(K12,$K$2:K$66) -> 19
A13: 12 | B13: 冯俊弛 | C13: 1271 | D13: ==VLOOKUP(B13,[1]在校生综合信息查询!$A$157:$C$222,2,0) -> 25q710103180 | E13: 6 | F13: 20 | G13: 18 | H13: 16 | I13: 16 | J13: 33 | K13: ==SUM(E13:J13) -> 109 | L13: ==RANK(K13,$K$2:K$66) -> 28
... A57: 56 | B57: 杨明博 | C57: 1306 | D57: ==VLOOKUP(B57,[1]在校生综合信息查询!$A$157:$C$222,2,0) -> 25q710103204 | E57: 12 | F57: 20 | G57: 9.5 | H57: 22 | I57: 16 | J57: 27 | K57: ==SUM(E57:J57) -> 106.5 | L57: ==RANK(K57,$K$2:K$66) -> 30
A58: 57 | B58: 杨宇涵 | D58: ==VLOOKUP(B58,[1]在校生综合信息查询!$A$157:$C$222,2,0) -> 25q710103174 | E58: 23 | F58: 24 | G58: 15.5 | H58: 30 | I58: 18 | J58: 22 | K58: ==SUM(E58:J58) -> 132.5 | L58: ==RANK(K58,$K$2:K$66) -> 17
A59: 58 | B59: 喻方虹 | D59: ==VLOOKUP(B59,[1]在校生综合信息查询!$A$157:$C$222,2,0) -> 25q710103263 | E59: 8 | F59: 28 | G59: 26.5 | H59: 22 | I59: 4 | J59: 28 | K59: ==SUM(E59:J59) -> 116.5 | L59: ==RANK(K59,$K$2:K$66) -> 23
A60: 59 | B60: 张建豪 | D60: ==VLOOKUP(B60,[1]在校生综合信息查询!$A$157:$C$222,2,0) -> 25q710103186 | E60: 0 | F60: 0 | G60: 21.5 | H60: 22 | I60: 12 | J60: 12 | K60: ==SUM(E60:J60) -> 67.5 | L60: ==RANK(K60,$K$2:K$66) -> 50
A61: 60 | B61: 章美玲 | D61: ==VLOOKUP(B61,[1]在校生综合信息查询!$A$157:$C$222,2,0) -> 25q710201157 | E61: 63 | F61: 12 | G61: 17 | H61: 16 | I61: 18 | J61: 21 | K61: ==SUM(E61:J61) -> 147 | L61: ==RANK(K61,$K$2:K$66) -> 14
A62: 61 | B62: 赵乐帆 | D62: ==VLOOKUP(B62,[1]在校生综合信息查询!$A$157:$C$222,2,0) -> 25q710103160 | E62: 43 | F62: 86 | G62: 17 | H62: 42 | I62: 31 | J62: 28 | K62: ==SUM(E62:J62) -> 247 | L62: ==RANK(K62,$K$2:K$66) -> 2
A63: 62 | B63: 赵文涛 | D63: ==VLOOKUP(B63,[1]在校生综合信息查询!$A$157:$C$222,2,0) -> 25q710103184 | E63: 36 | F63: 12 | G63: 19.5 | H63: 26 | I63: 10 | J63: 29 | K63: ==SUM(E63:J63) -> 132.5 | L63: ==RANK(K63,$K$2:K$66) -> 17
A64: 63 | B64: 周士杰 | D64: ==VLOOKUP(B64,[1]在校生综合信息查询!$A$157:$C$222,2,0) -> 25q660103084 | E64: 6 | F64: 17 | G64: 17 | H64: 14 | I64: 12 | J64: 15 | K64: ==SUM(E64:J64) -> 81 | L64: ==RANK(K64,$K$2:K$66) -> 42
A65: 64 | B65: 朱开洪 | D65: ==VLOOKUP(B65,[1]在校生综合信息查询!$A$157:$C$222,2,0) -> 25q710103203 | E65: 15 | F65: 16 | G65: 27.5 | H65: 26 | I65: 14 | J65: 18 | K65: ==SUM(E65:J65) -> 116.5 | L65: ==RANK(K65,$K$2:K$66) -> 23
A66: 65 | B66: 朱天祺 | D66: ==VLOOKUP(B66,[1]在校生综合信息查询!$A$157:$C$222,2,0) -> 25q710103353 | E66: 12 | F66: 12 | G66: 15 | H66: 14 | I66: 20 | J66: 15 | K66: ==SUM(E66:J66) -> 88 | L66: ==RANK(K66,$K$2:K$66) -> 40

Sheet 25级电子3班
A1: 序号 | B1: 姓名 | C1: 考号 | D1: 学号 | E1: 语文 | F1: 数学 | G1: 英语 | H1: 电工技术基础与技能实训 | I1: 电子技术基础与技能实训 | J1: 单片机技术与应用 | K1: 总分 | L1: 排名
A2: 1 | B2: 蔡嘉浩 | C2: 1635 | D2: ==VLOOKUP(B2,[1]在校生综合信息查询!$A$223:$C$293,2,0) -> 25q710103011 | E2: 8 | F2: 16 | G2: 20.5 | H2: 10 | I2: 16 | J2: 18
A3: 2 | B3: 曹予涵 | C3: 1648 | D3: ==VLOOKUP(B3,[1]在校生综合信息查询!$A$223:$C$293,2,0) -> 25q710103024 | E3: 12 | F3: 12 | G3: 17 | H3: 4 | I3: 6 | J3: 12
A4: 3 | B4: 曾海涛 | C4: 1667 | D4: ==VLOOKUP(B4,[1]在校生综合信息查询!$A$223:$C$293,2,0) -> 25q710103045 | E4: 18 | F4: 12 | G4: 22 | H4: 24 | I4: 14 | J4: 12
A5: 4 | B5: 车羽馨 | C5: 1684 | D5: ==VLOOKUP(B5,[1]在校生综合信息查询!$A$223:$C$293,2,0) -> 25q710103063 | E5: 1 | F5: 16 | G5: 18 | H5: 12 | I5: 18 | J5: 12
A6: 5 | B6: 陈玖霖 | C6: 1655 | D6: ==VLOOKUP(B6,[1]在校生综合信息查询!$A$223:$C$293,2,0) -> 25q710103031 | E6: 11 | F6: 24 | G6: 20 | H6: 12 | I6: 16 | J6: 21
A7: 6 | B7: 陈禹涵 | C7: 1636 | D7: ==VLOOKUP(B7,[1]在校生综合信息查询!$A$223:$C$293,2,0) -> 25q710103012 | E7: 0 | F7: 0 | G7: 0 | H7: 0 | I7: 0 | J7: 0
A8: 7 | B8: 丁宇霖 | C8: 1662 | D8: ==VLOOKUP(B8,[1]在校生综合信息查询!$A$223:$C$293,2,0) -> 25q710103040 | E8: 0 | F8: 16 | G8: 9.5 | H8: 22 | I8: 18 | J8: 21
A9: 8 | B9: 费正源 | C9: 1642 | D9: ==VLOOKUP(B9,[1]在校生综合信息查询!$A$223:$C$293,2,0) -> 25q710103018 | E9: 0 | F9: 0 | G9: 8.5 | H9: 12 | I9: 14 | J9: 33
A10: 9 | B10: 冯珺菲 | C10: 1634 | D10: ==VLOOKUP(B10,[1]在校生综合信息查询!$A$223:$C$293,2,0) -> 25q710103010 | E10: 31 | F10: 32 | G10: 18 | H10: 20 | I10: 10 | J10: 24
A11: 10 | B11: 冯岚 | C11: 1673 | D11: ==VLOOKUP(B11,[1]在校生综合信息查询!$A$223:$C$293,2,0) -> 25q710103052 | E11: 24 | F11: 8 | G11: 21.5 | H11: 18 | I11: 14 | J11: 24
A12: 11 | B12: 付雅兴 | C12: 1678 | D12: ==VLOOKUP(B12,[1]在校生综合信息查询!$A$223:$C$293,2,0) -> 25q710103057 | E12: 9 | F12: 12 | G12: 15.5 | H12: 22 | I12: 20 | J12: 21
A13: 12 | B13: 干舒雅 | C13: 1685 | D13: ==VLOOKUP(B13,[1]在校生综合信息查询!$A$223:$C$293,2,0) -> 25q710103064 | E13: 92 | F13: 36 | G13: 55.5 | H13: 22 | I13: 25 | J13: 33
... A18: 17 | B18: 黄楚云 | C18: 1672 | D18: ==VLOOKUP(B18,[1]在校生综合信息查询!$A$223:$C$293,2,0) -> 25q710103051 | E18: 0 | F18: 0 | G18: 0 | H18: 0 | I18: 0 | J18: 0
A19: 18 | B19: 黄雨婷 | C19: 1677 | D19: ==VLOOKUP(B19,[1]在校生综合信息查询!$A$223:$C$293,2,0) -> 25q710103056 | E19: 0 | F19: 0 | G19: 0
A20: 19 | B20: 蒋瑞杰 | C20: 1688 | D20: ==VLOOKUP(B20,[1]在校生综合信息查询!$A$223:$C$293,2,0) -> 25q710103352 | E20: 0 | F20: 8 | G20: 21 | H20: 12 | I20: 8 | J20: 21
A21: 20 | B21: 雷胡睿 | C21: 1628 | D21: ==VLOOKUP(B21,[1]在校生综合信息查询!$A$223:$C$293,2,0) -> 25q710103003 | E21: 26 | F21: 24 | G21: 16 | H21: 12 | I21: 10 | J21: 9
A22: 21 | B22: 李傲 | C22: 1660 | D22: ==VLOOKUP(B22,[1]在校生综合信息查询!$A$223:$C$293,2,0) -> 25q710103037 | E22: 18 | F22: 0 | G22: 24 | H22: 14 | I22: 14 | J22: 0
A23: 22 | B23: 李斌 | C23: 1654 | D23: ==VLOOKUP(B23,[1]在校生综合信息查询!$A$223:$C$293,2,0) -> 25q710103030 | E23: 13 | F23: 0 | G23: 0 | H23: 0 | I23: 0 | J23: 0
A24: 23 | B24: 李成涛 | C24: 1666 | D24: ==VLOOKUP(B24,[1]在校生综合信息查询!$A$223:$C$293,2,0) -> 25q710103044 | E24: 15 | F24: 12 | G24: 36.5 | H24: 12 | I24: 14 | J24: 28
A25: 24 | B25: 李峻熙 | C25: 1637 | D25: ==VLOOKUP(B25,[1]在校生综合信息查询!$A$223:$C$293,2,0) -> 25q710103013 | E25: 14 | F25: 0 | G25: 0 | H25: 14 | I25: 4 | J25: 12
A26: 25 | B26: 李添贵 | C26: 1695 | D26: ==VLOOKUP(B26,[1]在校生综合信息查询!$A$223:$C$293,2,0) -> 25q710201155 | E26: 0 | F26: 0 | G26: 0
A27: 26 | B27: 李威 | C27: 1630 | D27: ==VLOOKUP(B27,[1]在校生综合信息查询!$A$223:$C$293,2,0) -> 25q710103005 | E27: 0 | F27: 0 | G27: 0 | H27: 0 | I27: 0 | J27: 0
A28: 27 | B28: 李星宇 | C28: 1640 | D28: ==VLOOKUP(B28,[1]在校生综合信息查询!$A$223:$C$293,2,0) -> 25q710103016 | E28: 18 | F28: 12 | G28: 18 | H28: 14 | I28: 10 | J28: 20
A29: 28 | B29: 李梓源 | C29: 1625 | D29: ==VLOOKUP(B29,[1]在校生综合信息查询!$A$223:$C$293,2,0) -> 25q710103354 | E29: 0 | F29: 0 | G29: 0 | H29: 0 | I29: 0 | J29: 0
A30: 29 | B30: 刘崎序 | C30: 1658 | D30: ==VLOOKUP(B30,[1]在校生综合信息查询!$A$223:$C$293,2,0) -> 25q710103034 | E30: 44 | F30: 12 | G30: 17.5 | H30: 24 | I30: 24 | J30: 21
A31: 30 | B31: 刘洋 | C31: 1652 | D31: ==VLOOKUP(B31,[1]在校生综合信息查询!$A$223:$C$293,2,0) -> 25q710103028 | E31: 3 | F31: 16 | G31: 17 | H31: 24 | I31: 14 | J31: 24
A32: 31 | B32: 刘耀午 | C32: 1643 | D32: ==VLOOKUP(B32,[1]在校生综合信息查询!$A$223:$C$293,2,0) -> 25q710103019 | E32: 6 | F32: 16 | G32: 18 | H32: 18 | I32: 10 | J32: 21
A33: 32 | B33: 刘永泽 | C33: 1647 | D33: ==VLOOKUP(B33,[1]在校生综合信息查询!$A$223:$C$293,2,0) -> 25q710103023 | E33: 23 | F33: 36 | G33: 33 | H33: 10 | I33: 12 | J33: 33
A34: 33 | B34: 刘梓岚 | C34: 1694 | D34: ==VLOOKUP(B34,[1]在校生综合信息查询!$A$223:$C$293,2,0) -> 25q710103357 | E34: 0 | F34: 8 | G34: 26 | H34: 24 | I34: 0 | J34: 18
A35: 34 | B35: 卢俊林 | C35: 1644 | D35: ==VLOOKUP(B35,[1]在校生综合信息查询!$A$223:$C$293,2,0) -> 25q710103020 | E35: 24 | F35: 12 | G35: 20 | H35: 22 | I35: 16 | J35: 15
A36: 35 | B36: 罗怀豫 | C36: 1675 | D36: ==VLOOKUP(B36,[1]在校生综合信息查询!$A$223:$C$293,2,0) -> 25q710103007 | E36: 13 | F36: 8 | G36: 17 | H36: 16 | I36: 20 | J36: 24
A37: 36 | B37: 毛守毅 | C37: 1682 | D37: ==VLOOKUP(B37,[1]在校生综合信息查询!$A$223:$C$293,2,0) -> 25q710103043 | E37: 9 | F37: 24 | G37: 0 | H37: 0 | I37: 0 | J37: 0
A38: 37 | B38: 毛永顺 | C38: 1668 | D38: ==VLOOKUP(B38,[1]在校生综合信息查询!$A$223:$C$293,2,0) -> 25q710103014 | E38: 24 | F38: 20 | G38: 22 | H38: 24 | I38: 10 | J38: 18
A39: 38 | B39: 牟燕 | C39: 1686 | D39: ==VLOOKUP(B39,[1]在校生综合信息查询!$A$223:$C$293,2,0) -> 25q710103055 | E39: 23 | F39: 28 | G39: 16.5 | H39: 28 | I39: 10 | J39: 12
A40: 39 | B40: 欧阳 | C40: 1627 | D40: ==VLOOKUP(B40,[1]在校生综合信息查询!$A$223:$C$293,2,0) -> 25q710103042 | E40: 0 | F40: 0 | G40: 0
A41: 40 | B41: 彭雨怡 | C41: 1641 | D41: ==VLOOKUP(B41,[1]在校生综合信息查询!$A$223:$C$293,2,0) -> #N/A | E41: 0 | F41: 0 | G41: 0
A42: 41 | B42: 祁健文 | C42: 1646 | D42: ==VLOOKUP(B42,[1]在校生综合信息查询!$A$223:$C$293,2,0) -> 25q710103036 | E42: 0 | F42: 0 | G42: 0
A43: 42 | B43: 邱含宇 | C43: 1689 | D43: ==VLOOKUP(B43,[1]在校生综合信息查询!$A$223:$C$293,2,0) -> 25q710103015 | E43: 0 | F43: 0 | G43: 0 | H43: 0 | I43: 0 | J43: 0
A44: 43 | B44: 任雅坤 | C44: 1692 | D44: ==VLOOKUP(B44,[1]在校生综合信息查询!$A$223:$C$293,2,0) -> 25q710103026 | E44: 6 | F44: 0 | G44: 18.5 | H44: 16 | I44: 16 | J44: 15
...

Sheet 25级电子本方班
A1: 序号 | B1: 姓名 | C1: 考号 | D1: 学号 | E1: 语文 | F1: 数学 | G1: 英语 | H1: 电工技术基础与技能实训 | I1: 电子技术基础与技能实训 | J1: 总分 | K1: 排名
A2: 1 | B2: 白懿轩 | C2: 1873 | D2: ==VLOOKUP(B2,[1]在校生综合信息查询!$A$349:$C$404,2,0) -> 25q710103254 | E2: 74 | F2: 100 | G2: 33 | H2: 48 | I2: 42 | J2: ==E2+F2+G2+H2+I2 -> 297
A3: 2 | B3: 曹清华 | C3: 1879 | D3: ==VLOOKUP(B3,[1]在校生综合信息查询!$A$349:$C$404,2,0) -> 25q710103264 | E3: 63 | F3: 67 | G3: 48.5 | H3: 53 | I3: 56 | J3: ==E3+F3+G3+H3+I3 -> 287.5
A4: 3 | B4: 曹思婷 | C4: 1860 | D4: ==VLOOKUP(B4,[1]在校生综合信息查询!$A$349:$C$404,2,0) -> 25q710103237 | E4: 56 | F4: 20 | G4: 59.5 | H4: 27 | I4: 60 | J4: ==E4+F4+G4+H4+I4 -> 222.5
A5: 4 | B5: 曾宇森 | C5: 1888 | D5: ==VLOOKUP(B5,[1]在校生综合信息查询!$A$349:$C$404,2,0) -> 25q710103286 | E5: 79 | F5: 48 | G5: 19 | H5: 43 | I5: 52 | J5: ==E5+F5+G5+H5+I5 -> 241
A6: 5 | B6: 陈思雨 | C6: 1849 | D6: ==VLOOKUP(B6,[1]在校生综合信息查询!$A$349:$C$404,2,0) -> 25q710103224 | E6: 78 | F6: 69 | G6: 35 | H6: 32 | I6: 26 | J6: ==E6+F6+G6+H6+I6 -> 240
A7: 6 | B7: 陈祉函 | C7: 1857 | D7: ==VLOOKUP(B7,[1]在校生综合信息查询!$A$349:$C$404,2,0) -> 25q710103234 | E7: 75 | F7: 84 | G7: 25 | H7: 56 | I7: 42 | J7: ==E7+F7+G7+H7+I7 -> 282
A8: 7 | B8: 邓宋宏 | C8: 1880 | D8: ==VLOOKUP(B8,[1]在校生综合信息查询!$A$349:$C$404,2,0) -> 25q710103265 | E8: 73 | F8: 16 | G8: 47 | H8: 34 | I8: 24 | J8: ==E8+F8+G8+H8+I8 -> 194
A9: 8 | B9: 董洁 | C9: 1894 | D9: ==VLOOKUP(B9,[1]在校生综合信息查询!$A$349:$C$404,2,0) -> 25q710103266 | E9: 67 | F9: 32 | G9: 33 | H9: 22 | I9: 30 | J9: ==E9+F9+G9+H9+I9 -> 184
A10: 9 | B10: 樊宇杰 | C10: 1875 | D10: ==VLOOKUP(B10,[1]在校生综合信息查询!$A$349:$C$404,2,0) -> 25q710103256 | E10: 91 | F10: 108 | G10: 80.5 | H10: 58 | I10: 87 | J10: ==E10+F10+G10+H10+I10 -> 424.5
A11: 10 | B11: 冯俊棚 | C11: 1863 | D11: ==VLOOKUP(B11,[1]在校生综合信息查询!$A$349:$C$404,2,0) -> 25q710103240 | E11: 57 | F11: 115 | G11: 39 | H11: 62 | I11: 28 | J11: ==E11+F11+G11+H11+I11 -> 301
A12: 11 | B12: 冯裕翔 | C12: 1867 | D12: ==VLOOKUP(B12,[1]在校生综合信息查询!$A$349:$C$404,2,0) -> 25q710103246 | E12: 56 | F12: 69 | G12: 49 | H12: 30 | I12: 27 | J12: ==E12+F12+G12+H12+I12 -> 231
A13: 12 | B13: 付婷钰 | C13: 1859 | D13: ==VLOOKUP(B13,[1]在校生综合信息查询!$A$349:$C$404,2,0) -> 25q710103236 | E13: 89 | F13: 63 | G13: 39.5 | H13: 33 | I13: 32 | J13: ==E13+F13+G13+H13+I13 -> 256.5
... A15: 14 | B15: 胡宇婕 | C15: 1881 | D15: ==VLOOKUP(B15,[1]在校生综合信息查询!$A$349:$C$404,2,0) -> 25q710103268 | E15: 50 | F15: 16 | G15: 33.5 | H15: 29 | I15: 20 | J15: ==E15+F15+G15+H15+I15 -> 148.5
A16: 15 | B16: 黄萁菲 | C16: 1904 | D16: ==VLOOKUP(B16,[1]在校生综合信息查询!$A$349:$C$404,2,0) -> #N/A | E16: 74 | F16: 84 | G16: 50.5 | H16: 28 | J16: ==E16+F16+G16+H16+I16 -> 236.5
A17: 16 | B17: 黄琪胜 | C17: 1877 | D17: ==VLOOKUP(B17,[1]在校生综合信息查询!$A$349:$C$404,2,0) -> 25q710103260 | E17: 80 | F17: 62 | G17: 35 | H17: 32 | I17: 18 | J17: ==E17+F17+G17+H17+I17 -> 227
A18: 17 | B18: 黄鑫宇 | C18: 1902 | D18: ==VLOOKUP(B18,[1]在校生综合信息查询!$A$349:$C$404,2,0) -> 25q710201565 | E18: 86 | F18: 130 | G18: 62 | H18: 38 | I18: 68 | J18: ==E18+F18+G18+H18+I18 -> 384
A19: 18 | B19: 黄岩彬 | C19: 1850 | D19: ==VLOOKUP(B19,[1]在校生综合信息查询!$A$349:$C$404,2,0) -> 25q710103225 | E19: 96 | F19: 128 | G19: 39.5 | H19: 37 | I19: 47 | J19: ==E19+F19+G19+H19+I19 -> 347.5
A20: 19 | B20: 黄毅 | C20: 1899 | D20: ==VLOOKUP(B20,[1]在校生综合信息查询!$A$349:$C$404,2,0) -> 25q710201556 | E20: 89 | F20: 34 | G20: 46 | H20: 18 | I20: 16 | J20: ==E20+F20+G20+H20+I20 -> 203
A21: 20 | B21: 黄钰锴 | C21: 1896 | D21: ==VLOOKUP(B21,[1]在校生综合信息查询!$A$349:$C$404,2,0) -> 25q710103143 | E21: 59 | F21: 123 | G21: 25.5 | H21: 63 | I21: 60 | J21: ==E21+F21+G21+H21+I21 -> 330.5
A22: 21 | B22: 姜宇晨 | C22: 1874 | D22: ==VLOOKUP(B22,[1]在校生综合信息查询!$A$349:$C$404,2,0) -> 25q710103255 | E22: 70 | F22: 51 | G22: 38.5 | H22: 32 | I22: 28 | J22: ==E22+F22+G22+H22+I22 -> 219.5
A23: 22 | B23: 兰天宇 | C23: 1893 | D23: ==VLOOKUP(B23,[1]在校生综合信息查询!$A$349:$C$404,2,0) -> 25q710103259 | E23: 74 | F23: 39 | G23: 64 | H23: 27 | I23: 26 | J23: ==E23+F23+G23+H23+I23 -> 230
A24: 23 | B24: 李慧 | C24: 1869 | D24: ==VLOOKUP(B24,[1]在校生综合信息查询!$A$349:$C$404,2,0) -> 25q710103250 | E24: 67 | F24: 58 | G24: 48 | H24: 41 | I24: 36 | J24: ==E24+F24+G24+H24+I24 -> 250
A25: 24 | B25: 李茂熙 | C25: 1856 | D25: ==VLOOKUP(B25,[1]在校生综合信息查询!$A$349:$C$404,2,0) -> 25q710103232 | E25: 66 | F25: 53 | G25: 44.5 | H25: 37 | I25: 39 | J25: ==E25+F25+G25+H25+I25 -> 239.5
A26: 25 | B26: 李思鸿 | C26: 1892 | D26: ==VLOOKUP(B26,[1]在校生综合信息查询!$A$349:$C$404,2,0) -> 25q710103247 | E26: 75 | F26: 68 | G26: 39.5 | H26: 38 | I26: 21 | J26: ==E26+F26+G26+H26+I26 -> 241.5
A27: 26 | B27: 李紫仪 | C27: 1876 | D27: ==VLOOKUP(B27,[1]在校生综合信息查询!$A$349:$C$404,2,0) -> 25q710103258 | E27: 94 | F27: 113 | G27: 68 | H27: 51 | I27: 76 | J27: ==E27+F27+G27+H27+I27 -> 402
A28: 27 | B28: 凌海情 | C28: 1861 | D28: ==VLOOKUP(B28,[1]在校生综合信息查询!$A$349:$C$404,2,0) -> 25q710103238 | E28: 72 | F28: 34 | G28: 36.5 | H28: 33 | I28: 18 | J28: ==E28+F28+G28+H28+I28 -> 193.5
... A49: 48 | B49: 张莉 | C49: 1903 | D49: ==VLOOKUP(B49,[1]在校生综合信息查询!$A$349:$C$404,2,0) -> 25q710103253 | E49: 103 | F49: 83 | G49: 58 | H49: 38 | I49: 36 | J49: ==E49+F49+G49+H49+I49 -> 318
A50: 49 | B50: 张梦辉 | D50: ==VLOOKUP(B50,[1]在校生综合信息查询!$A$349:$C$404,2,0) -> 25q710103230 | E50: 48 | F50: 41 | G50: 13 | H50: 59 | I50: 24 | J50: ==E50+F50+G50+H50+I50 -> 185
A51: 50 | B51: 张饶意 | D51: ==VLOOKUP(B51,[1]在校生综合信息查询!$A$349:$C$404,2,0) -> 25q710103289 | E51: 84 | F51: 53 | G51: 27 | H51: 51 | I51: 27 | J51: ==E51+F51+G51+H51+I51 -> 242
A52: 51 | B52: 张维家 | D52: ==VLOOKUP(B52,[1]在校生综合信息查询!$A$349:$C$404,2,0) -> 20250719 | E52: 59 | F52: 59 | G52: 45 | H52: 22 | I52: 36 | J52: ==E52+F52+G52+H52+I52 -> 221
A53: 52 | B53: 张玉霖 | D53: ==VLOOKUP(B53,[1]在校生综合信息查询!$A$349:$C$404,2,0) -> 25q710103226 | E53: 77 | F53: 105 | G53: 44 | H53: 62 | I53: 26 | J53: ==E53+F53+G53+H53+I53 -> 314
A54: 53 | B54: 张梓林 | D54: ==VLOOKUP(B54,[1]在校生综合信息查询!$A$349:$C$404,2,0) -> 25q710103292 | E54: 76 | F54: 37 | G54: 54.5 | H54: 33 | I54: 22 | J54: ==E54+F54+G54+H54+I54 -> 222.5
A55: 54 | B55: 赵诗雅 | D55: ==VLOOKUP(B55,[1]在校生综合信息查询!$A$349:$C$404,2,0) -> 25q710103278 | E55: 61 | F55: 69 | G55: 58.5 | H55: 38 | I55: 34 | J55: ==E55+F55+G55+H55+I55 -> 260.5
A56: 55 | B56: 郑洋 | D56: ==VLOOKUP(B56,[1]在校生综合信息查询!$A$349:$C$404,2,0) -> 25q710103229 | E56: 48 | F56: 59 | G56: 29.5 | H56: 52 | I56: 25 | J56: ==E56+F56+G56+H56+I56 -> 213.5
A57: 56 | B57: 周思呈 | D57: ==VLOOKUP(B57,[1]在校生综合信息查询!$A$349:$C$404,2,0) -> 25q710103252 | E57: 80 | F57: 129 | G57: 42 | H57: 69 | I57: 86 | J57: ==E57+F57+G57+H57+I57 -> 406
A58: 57 | B58: 祝浩城 | D58: ==VLOOKUP(B58,[1]在校生综合信息查询!$A$349:$C$404,2,0) -> 25q710201568 | E58: 90 | F58: 76 | G58: 81.5 | H58: 28 | I58: 14 | J58: ==E58+F58+G58+H58+I58 -> 289.5

Sheet 25级电子职普融通班
A1: 序号 | B1: 姓名 | C1: 考号 | D1: 学号 | E1: 语文 | F1: 数学 | G1: 英语 | H1: 电工技术基础与技能实训 | I1: 电子技术基础与技能实训 | J1: 总分 | K1: 排名
A2: 1 | B2: 白金 | C2: 1053 | D2: ==VLOOKUP(B2,[1]在校生综合信息查询!$A$405:$C$447,2,0) -> 25q710103124 | E2: 38 | F2: 20 | G2: 18.5 | H2: 73 | I2: 80
A3: 2 | B3: 丁锐 | C3: 1085 | D3: ==VLOOKUP(B3,[1]在校生综合信息查询!$A$405:$C$447,2,0) -> 25q710103154 | E3: 59 | F3: 18 | G3: 32 | H3: 32 | I3: 30
A4: 3 | B4: 冯紫晗 | C4: 1083 | D4: ==VLOOKUP(B4,[1]在校生综合信息查询!$A$405:$C$447,2,0) -> 25q710103152 | E4: 66.5 | F4: 35 | G4: 66.5 | H4: 45 | I4: 56.5
A5: 4 | B5: 甘宇涵 | C5: 1062 | D5: ==VLOOKUP(B5,[1]在校生综合信息查询!$A$405:$C$447,2,0) -> 25q710103126 | E5: 75 | F5: 25 | G5: 46 | H5: 20 | I5: 36
A6: 5 | B6: 龚爱淋 | C6: 1084 | D6: ==VLOOKUP(B6,[1]在校生综合信息查询!$A$405:$C$447,2,0) -> 25q710103153 | E6: 66 | F6: 34 | G6: 53 | H6: 84 | I6: 79
A7: 6 | B7: 何博屹 | C7: 1058 | D7: ==VLOOKUP(B7,[1]在校生综合信息查询!$A$405:$C$447,2,0) -> 25q710103121 | E7: 72 | F7: 16 | G7: 34.5 | H7: 26 | I7: 34
A8: 7 | B8: 何耀祖 | C8: 1078 | D8: ==VLOOKUP(B8,[1]在校生综合信息查询!$A$405:$C$447,2,0) -> 25q710103142 | E8: 65 | F8: 5 | G8: 48 | H8: 26 | I8: 44
A9: 8 | B9: 何语晨 | C9: 1080 | D9: ==VLOOKUP(B9,[1]在校生综合信息查询!$A$405:$C$447,2,0) -> 25q710103149 | E9: 53 | F9: 94 | G9: 89 | H9: 34 | I9: 23
A10: 9 | B10: 黄浩然 | C10: 1059 | D10: ==VLOOKUP(B10,[1]在校生综合信息查询!$A$405:$C$447,2,0) -> 25q710103122 | E10: 85.5 | F10: 40 | G10: 21 | H10: 30 | I10: 30
A11: 10 | B11: 黄子轩 | C11: 1068 | D11: ==VLOOKUP(B11,[1]在校生综合信息查询!$A$405:$C$447,2,0) -> 25q710103132 | E11: 62.5 | F11: 10 | G11: 55 | H11: 58 | I11: 67
A12: 11 | B12: 黄紫萱 | C12: 1090 | D12: ==VLOOKUP(B12,[1]在校生综合信息查询!$A$405:$C$447,2,0) -> 25q710103161 | E12: 缺考 | F12: 缺考 | G12: 缺考
A13: 12 | B13: 李瑞杰 | C13: 1067 | D13: ==VLOOKUP(B13,[1]在校生综合信息查询!$A$405:$C$447,2,0) -> 25q710103131 | E13: 64 | F13: 20 | G13: 43.5 | H13: 36 | I13: 33.5
A14: 13 | B14: 李思成 | C14: 1089 | D14: ==VLOOKUP(B14,[1]在校生综合信息查询!$A$405:$C$447,2,0) -> 25q710103159 | E14: 61 | F14: 41 | G14: 42.5 | H14: 21 | I14: 37
A15: 14 | B15: 刘岚 | C15: 1074 | D15: ==VLOOKUP(B15,[1]在校生综合信息查询!$A$405:$C$447,2,0) -> 25q710103138 | E15: 70.5 | F15: 25 | G15: 31.5 | H15: 30 | I15: 48.5
A16: 15 | B16: 刘龙海 | C16: 1088 | D16: ==VLOOKUP(B16,[1]在校生综合信息查询!$A$405:$C$447,2,0) -> 25q710103158 | E16: 64.5 | F16: 23 | G16: 32 | H16: 44 | I16: 48.5
A17: 16 | B17: 刘诗雨 | C17: 1060 | D17: ==VLOOKUP(B17,[1]在校生综合信息查询!$A$405:$C$447,2,0) -> 25q710103123 | E17: 90 | F17: 82 | G17: 42 | H17: 31 | I17: 59.5
A18: 17 | B18: 罗茂棋 | C18: 1086 | D18: ==VLOOKUP(B18,[1]在校生综合信息查询!$A$405:$C$447,2,0) -> 25q710103155 | E18: 61 | F18: 22 | G18: 59 | H18: 57 | I18: 40.5
A19: 18 | B19: 罗思苒 | C19: 1056 | D19: ==VLOOKUP(B19,[1]在校生综合信息查询!$A$405:$C$447,2,0) -> 25q710103119 | E19: 67 | F19: 30 | G19: 98 | H19: 54 | I19: 39
A20: 19 | B20: 吕文涛 | C20: 1072 | D20: ==VLOOKUP(B20,[1]在校生综合信息查询!$A$405:$C$447,2,0) -> 25q710103136 | E20: 62.5 | F20: 16 | G20: 22.5 | H20: 48 | I20: 76
A21: 20 | B21: 吕芷妍 | C21: 1082 | D21: ==VLOOKUP(B21,[1]在校生综合信息查询!$A$405:$C$447,2,0) -> 25q710103151 | E21: 66 | F21: 67 | G21: 42.5 | H21: 62 | I21: 77
A22: 21 | B22: 宋唐贤 | C22: 1087 | D22: ==VLOOKUP(B22,[1]在校生综合信息查询!$A$405:$C$447,2,0) -> 25q710103156 | E22: 69 | F22: 32 | G22: 48 | H22: 49 | I22: 33.5
A23: 22 | B23: 王炳菻 | C23: 1075 | D23: ==VLOOKUP(B23,[1]在校生综合信息查询!$A$405:$C$447,2,0) -> 25q710103139 | E23: 68.5 | F23: 5 | G23: 66.5 | H23: 36 | I23: 77
A24: 23 | B24: 王柯宇 | C24: 1093 | D24: ==VLOOKUP(B24,[1]在校生综合信息查询!$A$405:$C$447,2,0) -> 20250702 | E24: 41 | F24: 41 | G24: 34.5 | H24: 29 | I24: 20
... A35: 34 | B35: 熊琨 | C35: 1063 | D35: ==VLOOKUP(B35,[1]在校生综合信息查询!$A$405:$C$447,2,0) -> 25q710103127 | E35: 64 | F35: 20 | G35: 23.5 | H35: 30 | I35: 30
A36: 35 | B36: 许晨析 | D36: ==VLOOKUP(B36,[1]在校生综合信息查询!$A$405:$C$447,2,0) -> 25q710103135 | E36: 66.5 | F36: 33 | G36: 34.5 | H36: 42 | I36: 29.5
A37: 36 | B37: 许林海 | D37: ==VLOOKUP(B37,[1]在校生综合信息查询!$A$405:$C$447,2,0) -> 25q710103125 | E37: 67 | F37: 44 | G37: 30 | H37: 77 | I37: 66
A38: 37 | B38: 杨檬玮 | D38: ==VLOOKUP(B38,[1]在校生综合信息查询!$A$405:$C$447,2,0) -> 25q710103162 | E38: 缺考 | F38: 缺考 | G38: 缺考
A39: 38 | B39: 杨宇星 | D39: ==VLOOKUP(B39,[1]在校生综合信息查询!$A$405:$C$447,2,0) -> 20250222 | E39: 66.5 | F39: 15 | G39: 48.5 | H39: 17 | I39: 49
A40: 39 | B40: 杨子一 | D40: ==VLOOKUP(B40,[1]在校生综合信息查询!$A$405:$C$447,2,0) -> 25q710103134 | E40: 75 | F40: 95 | G40: 51 | H40: 50 | I40: 53
A41: 40 | B41: 姚刘杰 | D41: ==VLOOKUP(B41,[1]在校生综合信息查询!$A$405:$C$447,2,0) -> 25q710103130 | E41: 61 | F41: 82 | G41: 45.5 | H41: 63 | I41: 80
A42: 41 | B42: 张宏博 | D42: ==VLOOKUP(B42,[1]在校生综合信息查询!$A$405:$C$447,2,0) -> 25q710103140 | E42: 81 | F42: 28 | G42: 36.5 | H42: 26 | I42: 30.5
A43: 42 | B43: 张宇豪 | D43: ==VLOOKUP(B43,[1]在校生综合信息查询!$A$405:$C$447,2,0) -> 25q710103129 | E43: 64.5 | F43: 25 | G43: 60.5 | H43: 27 | I43: 35
A44: 43 | B44: 张梓彤 | D44: ==VLOOKUP(B44,[1]在校生综合信息查询!$A$405:$C$447,2,0) -> 25q710103144 | E44: 52 | F44: 20 | G44: 56 | H44: 28 | I44: 54

Sheet 25级计算机1班
A1: 序号 | B1: 姓名 | C1: 考号 | D1: 学号 | E1: 语文 | F1: 数学 | G1: 英语 | H1: 办公软件应用 | I1: 信息技术应用基础 | J1: 总分 | K1: 排名
A2: 1 | B2: 曹逸辰 | C2: 1445 | D2: ==VLOOKUP(B2,[1]在校生综合信息查询!$A$448:$C$518,2,0) -> 25q710201054 | E2: 12 | F2: 4 | G2: 22.5 | H2: 14 | I2: 12 | J2: 64.5 | K2: ==RANK(J2,J$2:J$72,0) -> 59
A3: 2 | B3: 曹语涵 | C3: 1405 | D3: ==VLOOKUP(B3,[1]在校生综合信息查询!$A$448:$C$518,2,0) -> 25q710201210 | E3: 76 | F3: 20 | G3: 28 | H3: 63 | I3: 59 | J3: 246 | K3: ==RANK(J3,J$2:J$72,0) -> 2
A4: 3 | B4: 曾艳梅 | C4: 1422 | D4: ==VLOOKUP(B4,[1]在校生综合信息查询!$A$448:$C$518,2,0) -> 25q710201230 | E4: 52 | F4: 28 | G4: 35.5 | H4: 39 | I4: 35 | J4: 189.5 | K4: ==RANK(J4,J$2:J$72,0) -> 13
A5: 4 | B5: 曾宇琦 | C5: 1384 | D5: ==VLOOKUP(B5,[1]在校生综合信息查询!$A$448:$C$518,2,0) -> 25q710201184 | E5: 62 | F5: 8 | G5: 25.5 | H5: 45 | I5: 56 | J5: 196.5 | K5: ==RANK(J5,J$2:J$72,0) -> 11
A6: 5 | B6: 陈洪翔 | C6: 1401 | D6: ==VLOOKUP(B6,[1]在校生综合信息查询!$A$448:$C$518,2,0) -> 25q710201205 | E6: 60 | F6: 24 | G6: 23 | H6: 48 | I6: 43 | J6: 198 | K6: ==RANK(J6,J$2:J$72,0) -> 10
A7: 6 | B7: 陈靖豪 | C7: 1437 | D7: ==VLOOKUP(B7,[1]在校生综合信息查询!$A$448:$C$518,2,0) -> #N/A | E7: 26 | F7: 36 | G7: 23 | H7: 31 | I7: 46 | J7: 153.5 | K7: ==RANK(J7,J$2:J$72,0) -> 24
A8: 7 | B8: 陈林涛 | C8: 1429 | D8: ==VLOOKUP(B8,[1]在校生综合信息查询!$A$448:$C$518,2,0) -> 25q710201195 | E8: 46 | F8: 24 | G8: 25.5 | H8: 23 | I8: 26 | J8: 144.5 | K8: ==RANK(J8,J$2:J$72,0) -> 31
A9: 8 | B9: 陈心蝶 | C9: 1392 | D9: ==VLOOKUP(B9,[1]在校生综合信息查询!$A$448:$C$518,2,0) -> 25q710201194 | E9: 0 | F9: 0 | G9: 0 | J9: 0 | K9: ==RANK(J9,J$2:J$72,0) -> 63
A10: 9 | B10: 陈艳琳 | C10: 1379 | D10: ==VLOOKUP(B10,[1]在校生综合信息查询!$A$448:$C$518,2,0) -> 25q710201179 | E10: 53 | F10: 12 | G10: 22 | H10: 28 | I10: 36 | J10: 151 | K10: ==RANK(J10,J$2:J$72,0) -> 25
A11: 10 | B11: 陈煜杰 | C11: 1439 | D11: ==VLOOKUP(B11,[1]在校生综合信息查询!$A$448:$C$518,2,0) -> 24q710201007 | E11: 0 | F11: 0 | G11: 0 | J11: 0 | K11: ==RANK(J11,J$2:J$72,0) -> 63
A12: 11 | B12: 底诗琦 | C12: 1381 | D12: ==VLOOKUP(B12,[1]在校生综合信息查询!$A$448:$C$518,2,0) -> 25q710201181 | E12: 53 | F12: 12 | G12: 44.5 | H12: 33 | I12: 34 | J12: 176.5 | K12: ==RANK(J12,J$2:J$72,0) -> 18
A13: 12 | B13: 冯梦苒 | C13: 1418 | D13: ==VLOOKUP(B13,[1]在校生综合信息查询!$A$448:$C$518,2,0) -> 25q710201226 | E13: 15 | F13: 16 | G13: 32 | H13: 29 | I13: 29 | J13: 121 | K13: ==RANK(J13,J$2:J$72,0) -> 43
A14: 13 | B14: 龚晓菲 | C14: 1449 | D14: ==VLOOKUP(B14,[1]在校生综合信息查询!$A$448:$C$518,2,0) -> 25q710201062 | E14: 30 | F14: 24 | G14: 20.5 | H14: 27 | I14: 34 | J14: 135.5 | K14: ==RANK(J14,J$2:J$72,0) -> 37
A15: 14 | B15: 何荟兴 | C15: 1400 | D15: ==VLOOKUP(B15,[1]在校生综合信息查询!$A$448:$C$518,2,0) -> 25q710201204 | E15: 38 | F15: 18 | G15: 30.5 | H15: 59 | I15: 63 | J15: 208.5 | K15: ==RANK(J15,J$2:J$72,0) -> 7
A16: 15 | B16: 何欣瑞 | C16: 1390 | D16: ==VLOOKUP(B16,[1]在校生综合信息查询!$A$448:$C$518,2,0) -> 25q710201190 | E16: 11 | F16: 12 | G16: 21 | H16: 14 | I16: 26 | J16: 84 | K16: ==RANK(J16,J$2:J$72,0) -> 57
A17: 16 | B17: 何仲龄 | C17: 1440 | D17: ==VLOOKUP(B17,[1]在校生综合信息查询!$A$448:$C$518,2,0) -> 25q710201066 | E17: 6 | F17: 12 | G17: 20.5 | H17: 0 | I17: 0 | J17: 38.5 | K17: ==RANK(J17,J$2:J$72,0) -> 61
A18: 17 | B18: 黄嘉俊 | C18: 1414 | D18: ==VLOOKUP(B18,[1]在校生综合信息查询!$A$448:$C$518,2,0) -> 25q710201220 | E18: 2 | F18: 24 | G18: 22 | H18: 15 | I18: 26 | J18: 89 | K18: ==RANK(J18,J$2:J$72,0) -> 53
A19: 18 | B19: 黄轲诚 | C19: 1441 | D19: ==VLOOKUP(B19,[1]在校生综合信息查询!$A$448:$C$518,2,0) -> 25q710201068 | E19: 6 | F19: 28 | G19: 22.5 | H19: 19 | I19: 25 | J19: 100.5 | K19: ==RANK(J19,J$2:J$72,0) -> 50
A20: 19 | B20: 黄瑞 | C20: 1435 | D20: ==VLOOKUP(B20,[1]在校生综合信息查询!$A$448:$C$518,2,0) -> 25q710201244 | E20: 0 | F20: 0 | G20: 0 | J20: 0 | K20: ==RANK(J20,J$2:J$72,0) -> 63
A21: 20 | B21: 李昊 | C21: 1416 | D21: ==VLOOKUP(B21,[1]在校生综合信息查询!$A$448:$C$518,2,0) -> 25q710201222 | E21: 22 | F21: 20 | G21: 33 | H21: 15 | I21: 36 | J21: 126 | K21: ==RANK(J21,J$2:J$72,0) -> 41
A22: 21 | B22: 李会宁 | C22: 1383 | D22: ==VLOOKUP(B22,[1]在校生综合信息查询!$A$448:$C$518,2,0) -> 25q710201183 | E22: 60 | F22: 42 | G22: 68 | H22: 87 | I22: 58 | J22: ==SUM(E22,F22,G22,H22,I22) -> 315 | K22: ==RANK(J22,J$2:J$72,0) -> 1
A23: 22 | B23: 李晓美 | C23: 1394 | D23: ==VLOOKUP(B23,[1]在校生综合信息查询!$A$448:$C$518,2,0) -> 25q710201197 | E23: 37 | F23: 24 | G23: 19 | H23: 24 | I23: 32 | J23: 136 | K23: ==RANK(J23,J$2:J$72,0) -> 36
A24: 23 | B24: 李欣蕾 | C24: 1386 | D24: ==VLOOKUP(B24,[1]在校生综合信息查询!$A$448:$C$518,2,0) -> 25q710201186 | E24: 40 | F24: 24 | G24: 26 | H24: 55 | I24: 58 | J24: 203 | K24: ==RANK(J24,J$2:J$72,0) -> 8
A25: 24 | B25: 李宇航 | C25: 1415 | D25: ==VLOOKUP(B25,[1]在校生综合信息查询!$A$448:$C$518,2,0) -> 25q710201221 | E25: 39 | F25: 40 | G25: 50.5 | H25: 35 | I25: 44 | J25: 191.5 | K25: ==RANK(J25,J$2:J$72,0) -> 12
A26: 25 | B26: 凌星铖 | C26: 1420 | D26: ==VLOOKUP(B26,[1]在校生综合信息查询!$A$448:$C$518,2,0) -> 25q710201228 | E26: 9 | F26: 12 | G26: 16 | H26: 23 | I26: 30 | J26: 150 | K26: ==RANK(J26,J$2:J$72,0) -> 27
A27: 26 | B27: 刘浩 | C27: 1421 | D27: ==VLOOKUP(B27,[1]在校生综合信息查询!$A$448:$C$518,2,0) -> 25q710201229 | E27: 41 | F27: 12 | G27: 15 | H27: 22 | I27: 41 | J27: 131 | K27: ==RANK(J27,J$2:J$72,0) -> 39
A28: 27 | B28: 刘俊熙 | C28: 1391 | D28: ==VLOOKUP(B28,[1]在校生综合信息查询!$A$448:$C$518,2,0) -> 25q710201191 | E28: 15 | F28: 20 | G28: 10.5 | H28: 23 | I28: 18 | J28: 81.5 | K28: ==RANK(J28,J$2:J$72,0) -> 58
A29: 28 | B29: 刘峻巧 | C29: 1410 | D29: ==VLOOKUP(B29,[1]在校生综合信息查询!$A$448:$C$518,2,0) -> 25q710201215 | E29: 0 | F29: 0 | G29: 0 | J29: 0 | K29: ==RANK(J29,J$2:J$72,0) -> 63
A30: 29 | B30: 刘珊 | C30: 1425 | D30: ==VLOOKUP(B30,[1]在校生综合信息查询!$A$448:$C$518,2,0) -> 25q710201236 | E30: 50 | F30: 33 | G30: 21 | H30: 31 | I30: 41 | J30: 176 | K30: ==RANK(J30,J$2:J$72,0) -> 19
A31: 30 | B31: 龙依晨 | C31: 1385 | D31: ==VLOOKUP(B31,[1]在校生综合信息查询!$A$448:$C$518,2,0) -> 25q710201185 | E31: 62 | F31: 12 | G31: 31.5 | H31: 18 | I31: 22 | J31: 145.5 | K31: ==RANK(J31,J$2:J$72,0) -> 30
A32: 31 | B32: 罗嘉欣 | C32: 1403 | D32: ==VLOOKUP(B32,[1]在校生综合信息查询!$A$448:$C$518,2,0) -> 25q710201207 | E32: 19 | F32: 28 | G32: 29 | H32: 24 | I32: 18 | J32: 118 | K32: ==RANK(J32,J$2:J$72,0) -> 45
A33: 32 | B33: 罗奇 | C33: 1393 | D33: ==VLOOKUP(B33,[1]在校生综合信息查询!$A$448:$C$518,2,0) -> 25q710201196 | E33: 17 | F33: 20 | G33: 24 | H33: 29 | I33: 48 | J33: 138 | K33: ==RANK(J33,J$2:J$72,0) -> 32
A34: 33 | B34: 罗思瑞 | C34: 1397 | D34: ==VLOOKUP(B34,[1]在校生综合信息查询!$A$448:$C$518,2,0) -> 25q710201201 | E34: 0 | F34: 0 | G34: 0 | J34: 0 | K34: ==RANK(J34,J$2:J$72,0) -> 63
A35: 34 | B35: 罗星浩 | C35: 1436 | D35: ==VLOOKUP(B35,[1]在校生综合信息查询!$A$448:$C$518,2,0) -> 25q710201245 | E35: 18 | F35: 16 | G35: 16 | H35: 15 | I35: 24 | J35: 89 | K35: ==RANK(J35,J$2:J$72,0) -> 53
A36: 35 | B36: 罗云翔 | C36: 1382 | D36: ==VLOOKUP(B36,[1]在校生综合信息查询!$A$448:$C$518,2,0) -> 25q710201078 | E36: 22 | F36: 12 | G36: 22.5 | H36: 37 | I36: 27 | J36: 120.5 | K36: ==RANK(J36,J$2:J$72,0) -> 44
A37: 36 | B37: 穆杨 | C37: 1387 | D37: ==VLOOKUP(B37,[1]在校生综合信息查询!$A$448:$C$518,2,0) -> 25q710201235 | E37: 34 | F37: 20 | G37: 14 | H37: 28 | I37: 34 | J37: 130 | K37: ==RANK(J37,J$2:J$72,0) -> 40
A38: 37 | B38: 彭成洪 | C38: 1399 | D38: ==VLOOKUP(B38,[1]在校生综合信息查询!$A$448:$C$518,2,0) -> 25q710201081 | E38: 25 | F38: 28 | G38: 22.5 | H38: 47 | I38: 41 | J38: 163.5 | K38: ==RANK(J38,J$2:J$72,0) -> 23
A39: 38 | B39: 宋慧慈 | C39: 1402 | D39: ==VLOOKUP(B39,[1]在校生综合信息查询!$A$448:$C$518,2,0) -> 25q710201189 | E39: 0 | F39: 0 | G39: 0 | J39: 0 | K39: ==RANK(J39,J$2:J$72,0) -> 63
A40: 39 | B40: 宋慧敏 | C40: 1423 | D40: ==VLOOKUP(B40,[1]在校生综合信息查询!$A$448:$C$518,2,0) -> 25q710201213 | E40: 26 | F40: 16 | G40: 43.5 | H40: 53 | I40: 61 | J40: 199.5 | K40: ==RANK(J40,J$2:J$72,0) -> 9
...

Sheet 25级计算机2班
A1: 序号 | B1: 姓名 | C1: 考号 | D1: 学号 | E1: 语文 | F1: 数学 | G1: 英语 | H1: 办公软件应用 | I1: 信息技术应用基础 | J1: 总分 | K1: 排名
A2: 1 | B2: 陈彬炜 | C2: 1244 | D2: ==VLOOKUP(B2,[1]在校生综合信息查询!$A$519:$C$591,2,0) -> 25q710103287 | E2: 14 | F2: 20 | G2: 24 | H2: 25 | I2: 32
A3: 2 | B3: 陈翰霖 | C3: 1200 | D3: ==VLOOKUP(B3,[1]在校生综合信息查询!$A$519:$C$591,2,0) -> 25q710201126 | E3: 40 | F3: 48 | G3: 8.5 | H3: 60 | I3: 54
A4: 3 | B4: 陈俊麒 | C4: 1252 | D4: ==VLOOKUP(B4,[1]在校生综合信息查询!$A$519:$C$591,2,0) -> 25q710201055 | E4: 54 | F4: 20 | G4: 24 | H4: 51 | I4: 63
A5: 4 | B5: 陈锟 | C5: 1234 | D5: ==VLOOKUP(B5,[1]在校生综合信息查询!$A$519:$C$591,2,0) -> 25q710201167 | E5: 16 | F5: 12 | G5: 24.5 | H5: 23 | I5: 31
A6: 5 | B6: 陈孟瑶 | C6: 1214 | D6: ==VLOOKUP(B6,[1]在校生综合信息查询!$A$519:$C$591,2,0) -> 25q710201142 | E6: 5 | F6: 16 | G6: 27.5 | H6: 19 | I6: 32
A7: 6 | B7: 陈瑞洋 | C7: 1253 | D7: ==VLOOKUP(B7,[1]在校生综合信息查询!$A$519:$C$591,2,0) -> 25q770303025 | E7: 9 | F7: 12 | G7: 18 | H7: 22 | I7: 16
A8: 7 | B8: 陈心语 | C8: 1209 | D8: ==VLOOKUP(B8,[1]在校生综合信息查询!$A$519:$C$591,2,0) -> 25q710201136 | E8: 58 | F8: 47 | G8: 51.5 | H8: 66 | I8: 61
A9: 8 | B9: 陈炫 | C9: 1207 | D9: ==VLOOKUP(B9,[1]在校生综合信息查询!$A$519:$C$591,2,0) -> 25q710201133 | E9: 37 | F9: 16 | G9: 22 | H9: 19 | I9: 38
A10: 9 | B10: 底涵曦 | C10: 1239 | D10: ==VLOOKUP(B10,[1]在校生综合信息查询!$A$519:$C$591,2,0) -> 25q710201174 | E10: 35 | F10: 24 | G10: 14.5 | H10: 41 | I10: 48
A11: 10 | B11: 丁思雨 | C11: 1235 | D11: ==VLOOKUP(B11,[1]在校生综合信息查询!$A$519:$C$591,2,0) -> 25q710201170 | E11: 15 | F11: 24 | G11: 23 | H11: 26 | I11: 23
A12: 11 | B12: 董峻濠 | C12: 1237 | D12: ==VLOOKUP(B12,[1]在校生综合信息查询!$A$519:$C$591,2,0) -> 25q710201172 | E12: 3 | F12: 24 | G12: 10 | H12: 17 | I12: 36
A13: 12 | B13: 樊诗娇 | C13: 1211 | D13: ==VLOOKUP(B13,[1]在校生综合信息查询!$A$519:$C$591,2,0) -> 25q710201138 | E13: 0 | F13: 0 | G13: 0
A14: 13 | B14: 符美婷 | C14: 1193 | D14: ==VLOOKUP(B14,[1]在校生综合信息查询!$A$519:$C$591,2,0) -> 25q710201119 | E14: 44 | F14: 28 | G14: 18 | H14: 31 | I14: 33
A15: 14 | B15: 何贵鑫 | C15: 1247 | D15: ==VLOOKUP(B15,[1]在校生综合信息查询!$A$519:$C$591,2,0) -> 25q710103267 | E15: 9 | F15: 12 | G15: 13.5 | H15: 33 | I15: 36
A16: 15 | B16: 何一帆 | C16: 1228 | D16: ==VLOOKUP(B16,[1]在校生综合信息查询!$A$519:$C$591,2,0) -> 25q710201158 | E16: 25 | F16: 12 | G16: 15.5 | H16: 27 | I16: 25
A17: 16 | B17: 侯佳怡 | C17: 1232 | D17: ==VLOOKUP(B17,[1]在校生综合信息查询!$A$519:$C$591,2,0) -> 25q710201164 | E17: 36 | F17: 28 | G17: 31 | H17: 34 | I17: 46
A18: 17 | B18: 胡贾琦 | C18: 1242 | D18: ==VLOOKUP(B18,[1]在校生综合信息查询!$A$519:$C$591,2,0) -> 25q710201178 | E18: 21 | F18: 20 | G18: 25 | H18: 10 | I18: 30
A19: 18 | B19: 黄玲 | C19: 1258 | D19: ==VLOOKUP(B19,[1]在校生综合信息查询!$A$519:$C$591,2,0) -> #N/A | E19: 12 | F19: 16 | G19: 18.5 | H19: 18 | I19: 28
A20: 19 | B20: 黄森磊 | C20: 1205 | D20: ==VLOOKUP(B20,[1]在校生综合信息查询!$A$519:$C$591,2,0) -> 25q710201131 | E20: 36 | F20: 36 | G20: 23 | H20: 30 | I20: 45
A21: 20 | B21: 黄宇诗 | C21: 1238 | D21: ==VLOOKUP(B21,[1]在校生综合信息查询!$A$519:$C$591,2,0) -> 25q710201173 | E21: 44 | F21: 28 | G21: 24.5 | H21: 63 | I21: 80
A22: 21 | B22: 简晨曦 | C22: 1245 | D22: ==VLOOKUP(B22,[1]在校生综合信息查询!$A$519:$C$591,2,0) -> 25q710103288 | E22: 21 | F22: 20 | G22: 12.5 | H22: 26 | I22: 32
A23: 22 | B23: 金鑫磊 | C23: 1236 | D23: ==VLOOKUP(B23,[1]在校生综合信息查询!$A$519:$C$591,2,0) -> 25q710201171 | E23: 6 | F23: 16 | G23: 15 | H23: 15 | I23: 36
A24: 23 | B24: 李航宇 | C24: 1210 | D24: ==VLOOKUP(B24,[1]在校生综合信息查询!$A$519:$C$591,2,0) -> 25q710201137 | E24: 64 | F24: 36 | G24: 22 | H24: 43 | I24: 56
A25: 24 | B25: 李诗杨 | C25: 1204 | D25: ==VLOOKUP(B25,[1]在校生综合信息查询!$A$519:$C$591,2,0) -> 25q710201130 | E25: 39 | F25: 24 | G25: 23.5 | H25: 46 | I25: 48
... A48: 47 | B48: 许恒歌 | C48: 1218 | D48: ==VLOOKUP(B48,[1]在校生综合信息查询!$A$519:$C$591,2,0) -> 25q710103275 | E48: 21 | F48: 12 | G48: 18.5 | H48: 20 | I48: 37
A49: 48 | B49: 严懿宸 | C49: 1196 | D49: ==VLOOKUP(B49,[1]在校生综合信息查询!$A$519:$C$591,2,0) -> 25q710201099 | E49: 0 | F49: 0 | G49: 0 | I49: 0
A50: 49 | B50: 杨文琴 | C50: 1249 | D50: ==VLOOKUP(B50,[1]在校生综合信息查询!$A$519:$C$591,2,0) -> 25q710201145 | E50: 47 | F50: 20 | G50: 23 | H50: 41 | I50: 48
A51: 50 | B51: 杨曦 | C51: 1201 | D51: ==VLOOKUP(B51,[1]在校生综合信息查询!$A$519:$C$591,2,0) -> 25q710201154 | E51: 34 | F51: 12 | G51: 20.5 | H51: 35 | I51: 41
A52: 51 | B52: 尹淅瑶 | C52: 1248 | D52: ==VLOOKUP(B52,[1]在校生综合信息查询!$A$519:$C$591,2,0) -> 25q710201123 | E52: 66 | F52: 48 | G52: 58 | H52: 50 | I52: 56
A53: 52 | B53: 余爱杨 | C53: 1221 | D53: ==VLOOKUP(B53,[1]在校生综合信息查询!$A$519:$C$591,2,0) -> 25q710201140 | E53: 0 | F53: 20 | G53: 17.5 | H53: 16 | I53: 36
A54: 53 | B54: 余承熹 | C54: 1215 | D54: ==VLOOKUP(B54,[1]在校生综合信息查询!$A$519:$C$591,2,0) -> 25q710201121 | E54: 62 | F54: 48 | G54: 41.5 | H54: 49 | I54: 56
A55: 54 | B55: 余东洋 | C55: 1250 | D55: ==VLOOKUP(B55,[1]在校生综合信息查询!$A$519:$C$591,2,0) -> 25q710201148 | E55: 42 | F55: 20 | G55: 31.5 | H55: 22 | I55: 41
A56: 55 | B56: 余富成 | C56: 1206 | D56: ==VLOOKUP(B56,[1]在校生综合信息查询!$A$519:$C$591,2,0) -> 25q710201161 | E56: 50 | F56: 20 | G56: 14.5 | H56: 50 | I56: 56
A57: 56 | B57: 余静 | C57: 1229 | D57: ==VLOOKUP(B57,[1]在校生综合信息查询!$A$519:$C$591,2,0) -> 25q710201146 | E57: 38 | F57: 12 | G57: 17.5 | H57: 58 | I57: 62
A58: 57 | B58: 袁宇薇 | C58: 1251 | D58: ==VLOOKUP(B58,[1]在校生综合信息查询!$A$519:$C$591,2,0) -> 25q710201122 | E58: 62 | F58: 60 | G58: 58.5 | H58: 54 | I58: 54
A59: 58 | B59: 袁长帅 | C59: 1202 | D59: ==VLOOKUP(B59,[1]在校生综合信息查询!$A$519:$C$591,2,0) -> 25q770303007 | E59: 9 | F59: 16 | G59: 24.5 | H59: 20 | I59: 30
A60: 59 | B60: 张贝依 | D60: ==VLOOKUP(B60,[1]在校生综合信息查询!$A$519:$C$591,2,0) -> 25q710201127 | E60: 0 | F60: 0 | G60: 0 | I60: 0
A61: 60 | B61: 张猛淋 | D61: ==VLOOKUP(B61,[1]在校生综合信息查询!$A$519:$C$591,2,0) -> 25q710201107 | E61: 67 | F61: 28 | G61: 13.5 | H61: 50 | I61: 52
A62: 61 | B62: 张诗敏 | D62: ==VLOOKUP(B62,[1]在校生综合信息查询!$A$519:$C$591,2,0) -> 25q710201149 | E62: 52 | F62: 16 | G62: 10.5 | H62: 49 | I62: 44
...

Sheet 25级计算机本方班
A1: 序号 | B1: 姓名 | C1: 考号 | D1: 学号 | E1: 语文 | F1: 数学 | G1: 英语 | H1: 办公软件应用 | I1: 信息技术应用基础 | J1: 总分 | K1: 排名
A2: 1 | B2: 曾家苗 | C2: 1839 | D2: ==VLOOKUP(B2,[1]在校生综合信息查询!$A$592:$C$648,2,0) -> 25q710201117 | E2: 56 | F2: 76 | G2: 58 | H2: 59 | I2: 53 | J2: ==SUM(E2,F2,G2,H2,I2) -> 302 | K2: ==RANK(J2,$J$2:$J$58,0) -> 34
A3: 2 | B3: 曾欣雨 | C3: 1840 | D3: ==VLOOKUP(B3,[1]在校生综合信息查询!$A$592:$C$648,2,0) -> 25q710201118 | E3: 100 | F3: 79 | G3: 34 | H3: 78 | I3: 68 | J3: ==SUM(E3,F3,G3,H3,I3) -> 359 | K3: ==RANK(J3,$J$2:$J$58,0) -> 8
A4: 3 | B4: 陈雅薇 | C4: 1794 | D4: ==VLOOKUP(B4,[1]在校生综合信息查询!$A$592:$C$648,2,0) -> 25q710201056 | E4: 104 | F4: 52 | G4: 73.5 | H4: 72 | I4: 63 | J4: ==SUM(E4,F4,G4,H4,I4) -> 364.5 | K4: ==RANK(J4,$J$2:$J$58,0) -> 5
A5: 4 | B5: 程澳蕾 | C5: 1795 | D5: ==VLOOKUP(B5,[1]在校生综合信息查询!$A$592:$C$648,2,0) -> 25q710201057 | E5: 60 | F5: 36 | G5: 0 | I5: 0 | J5: ==SUM(E5,F5,G5,H5,I5) -> 96 | K5: ==RANK(J5,$J$2:$J$58,0) -> 55
A6: 5 | B6: 杜萧雅 | C6: 1796 | D6: ==VLOOKUP(B6,[1]在校生综合信息查询!$A$592:$C$648,2,0) -> 25q710201058 | E6: 69 | F6: 16 | G6: 30.5 | H6: 50 | I6: 65 | J6: ==SUM(E6,F6,G6,H6,I6) -> 230.5 | K6: ==RANK(J6,$J$2:$J$58,0) -> 48
A7: 6 | B7: 冯韵涵 | C7: 1797 | D7: ==VLOOKUP(B7,[1]在校生综合信息查询!$A$592:$C$648,2,0) -> 25q710201059 | E7: 77 | F7: 27 | G7: 34.5 | H7: 42 | I7: 65 | J7: ==SUM(E7,F7,G7,H7,I7) -> 245.5 | K7: ==RANK(J7,$J$2:$J$58,0) -> 46
A8: 7 | B8: 付海岭 | C8: 1798 | D8: ==VLOOKUP(B8,[1]在校生综合信息查询!$A$592:$C$648,2,0) -> 25q710201060 | E8: 79 | F8: 56 | G8: 60.5 | H8: 55 | I8: 70 | J8: ==SUM(E8,F8,G8,H8,I8) -> 320.5 | K8: ==RANK(J8,$J$2:$J$58,0) -> 27
A9: 8 | B9: 龚宁 | C9: 1799 | D9: ==VLOOKUP(B9,[1]在校生综合信息查询!$A$592:$C$648,2,0) -> 25q710201061 | E9: 38 | F9: 28 | G9: 53 | H9: 47 | I9: 41 | J9: ==SUM(E9,F9,G9,H9,I9) -> 207 | K9: ==RANK(J9,$J$2:$J$58,0) -> 50
A10: 9 | B10: 郭锦瑶 | C10: 1792 | D10: ==VLOOKUP(B10,[1]在校生综合信息查询!$A$592:$C$648,2,0) -> 24q710103189 | E10: 107 | F10: 123 | G10: 73 | H10: 88 | I10: 75 | J10: ==SUM(E10,F10,G10,H10,I10) -> 466 | K10: ==RANK(J10,$J$2:$J$58,0) -> 1
A11: 10 | B11: 郭柳盛 | C11: 1800 | D11: ==VLOOKUP(B11,[1]在校生综合信息查询!$A$592:$C$648,2,0) -> 25q710201063 | E11: 82 | F11: 25 | G11: 39.5 | H11: 81 | I11: 60 | J11: ==SUM(E11,F11,G11,H11,I11) -> 287.5 | K11: ==RANK(J11,$J$2:$J$58,0) -> 38
A12: 11 | B12: 韩雨娇 | C12: 1841 | D12: ==VLOOKUP(B12,[1]在校生综合信息查询!$A$592:$C$648,2,0) -> 25q710201064 | E12: 0 | F12: 0 | G12: 0 | I12: 0 | J12: ==SUM(E12,F12,G12,H12,I12) -> 0 | K12: ==RANK(J12,$J$2:$J$58,0) -> 57
A13: 12 | B13: 何荟颖 | C13: 1842 | D13: ==VLOOKUP(B13,[1]在校生综合信息查询!$A$592:$C$648,2,0) -> 25q710201065 | E13: 75 | F13: 102 | G13: 63 | H13: 77 | I13: 84 | J13: ==SUM(E13,F13,G13,H13,I13) -> 401 | K13: ==RANK(J13,$J$2:$J$58,0) -> 2
A14: 13 | B14: 侯雅琴 | C14: 1801 | D14: ==VLOOKUP(B14,[1]在校生综合信息查询!$A$592:$C$648,2,0) -> 25q710201067 | E14: 95 | F14: 77 | G14: 49.5 | H14: 68 | I14: 67 | J14: ==SUM(E14,F14,G14,H14,I14) -> 356.5 | K14: ==RANK(J14,$J$2:$J$58,0) -> 10
A15: 14 | B15: 黄玉柳 | C15: 1802 | D15: ==VLOOKUP(B15,[1]在校生综合信息查询!$A$592:$C$648,2,0) -> 25q710201069 | E15: 87 | F15: 115 | G15: 30 | H15: 79 | I15: 70 | J15: ==SUM(E15,F15,G15,H15,I15) -> 381 | K15: ==RANK(J15,$J$2:$J$58,0) -> 3
A16: 15 | B16: 蒋天豪 | C16: 1843 | D16: ==VLOOKUP(B16,[1]在校生综合信息查询!$A$592:$C$648,2,0) -> 25q660103097 | E16: 85 | F16: 98 | G16: 47.5 | H16: 65 | I16: 63 | J16: ==SUM(E16,F16,G16,H16,I16) -> 358.5 | K16: ==RANK(J16,$J$2:$J$58,0) -> 9
A17: 16 | B17: 李晨曦 | C17: 1844 | D17: ==VLOOKUP(B17,[1]在校生综合信息查询!$A$592:$C$648,2,0) -> 25q710103146 | E17: 57 | F17: 24 | G17: 61.5 | H17: 52 | I17: 56 | J17: ==SUM(E17,F17,G17,H17,I17) -> 250.5 | K17: ==RANK(J17,$J$2:$J$58,0) -> 45
A18: 17 | B18: 李璟洋 | C18: 1803 | D18: ==VLOOKUP(B18,[1]在校生综合信息查询!$A$592:$C$648,2,0) -> 25q710201070 | E18: 72 | F18: 24 | G18: 65.5 | H18: 83 | I18: 66 | J18: ==SUM(E18,F18,G18,H18,I18) -> 310.5 | K18: ==RANK(J18,$J$2:$J$58,0) -> 33
A19: 18 | B19: 李璐邑 | C19: 1804 | D19: ==VLOOKUP(B19,[1]在校生综合信息查询!$A$592:$C$648,2,0) -> 25q710201071 | E19: 77 | F19: 35 | G19: 23 | H19: 68 | I19: 61 | J19: ==SUM(E19,F19,G19,H19,I19) -> 264 | K19: ==RANK(J19,$J$2:$J$58,0) -> 43
A20: 19 | B20: 李想 | C20: 1845 | D20: ==VLOOKUP(B20,[1]在校生综合信息查询!$A$592:$C$648,2,0) -> 25q710201559 | E20: 79 | F20: 40 | G20: 78 | H20: 83 | I20: 69 | J20: ==SUM(E20,F20,G20,H20,I20) -> 349 | K20: ==RANK(J20,$J$2:$J$58,0) -> 13
A21: 20 | B21: 李雨宏 | C21: 1805 | D21: ==VLOOKUP(B21,[1]在校生综合信息查询!$A$592:$C$648,2,0) -> 25q710201072 | E21: 67 | F21: 28 | G21: 15 | H21: 64 | I21: 43 | J21: ==SUM(E21,F21,G21,H21,I21) -> 217 | K21: ==RANK(J21,$J$2:$J$58,0) -> 49
A22: 21 | B22: 刘红玫 | C22: 1806 | D22: ==VLOOKUP(B22,[1]在校生综合信息查询!$A$592:$C$648,2,0) -> 25q710201073 | E22: 89 | F22: 43 | G22: 58 | H22: 62 | I22: 71 | J22: ==SUM(E22,F22,G22,H22,I22) -> 323 | K22: ==RANK(J22,$J$2:$J$58,0) -> 26
A23: 22 | B23: 刘红艳 | C23: 1807 | D23: ==VLOOKUP(B23,[1]在校生综合信息查询!$A$592:$C$648,2,0) -> 25q710201074 | E23: 95 | F23: 68 | G23: 29 | H23: 68 | I23: 67 | J23: ==SUM(E23,F23,G23,H23,I23) -> 327 | K23: ==RANK(J23,$J$2:$J$58,0) -> 24
A24: 23 | B24: 刘晓荟 | C24: 1808 | D24: ==VLOOKUP(B24,[1]在校生综合信息查询!$A$592:$C$648,2,0) -> 25q710201075 | E24: 90 | F24: 47 | G24: 55.5 | H24: 79 | I24: 65 | J24: ==SUM(E24,F24,G24,H24,I24) -> 336.5 | K24: ==RANK(J24,$J$2:$J$58,0) -> 20
... A48: 47 | B48: 余沁洨 | C48: 1846 | D48: ==VLOOKUP(B48,[1]在校生综合信息查询!$A$592:$C$648,2,0) -> 25q710201104 | E48: 81 | F48: 25 | G48: 47.5 | H48: 44 | I48: 42 | J48: ==SUM(E48,F48,G48,H48,I48) -> 239.5 | K48: ==RANK(J48,$J$2:$J$58,0) -> 47
A49: 48 | B49: 余思瑶 | D49: ==VLOOKUP(B49,[1]在校生综合信息查询!$A$592:$C$648,2,0) -> 25q710201105 | E49: 86 | F49: 28 | G49: 37 | H49: 75 | I49: 61 | J49: ==SUM(E49,F49,G49,H49,I49) -> 287 | K49: ==RANK(J49,$J$2:$J$58,0) -> 39
